Workbook

Sheet ⚙ Control Panel
A1: ⚙ CONTROL PANEL — Edit dropdowns and master values here
A4: Salespersons | C4: Stage | E4: Segment | G4: Priority
A5: Mew | C5: Interest | E5: Gov | G5: High
A6: Napat | C6: Send PI | E6: Private | G6: Medium
A7: Tan | C7: Negotiating | G7: Low
A8: Aoey | C8: Deal Signed
A9: Other Sales | C9: Delivered
C10: Lost
A13: Product Category | C13: Brand | E13: Fee Structure | G13: Specialization
A14: Steel | C14: Sunon | E14: Referral % | G14: Office
A15: Chair | C15: Taiyo | E15: No fee | G15: Hospital & Wellness
A16: Wooden | C16: Motech | E16: Client to resell | G16: Education
C17: Hybrida | G17: Government
C18: Other
A22: Monthly Target (THB) | C22: ℹ️ Instructions
A23: 3000000 | C23: • Edit dropdown lists in the columns above
C24: • Add a new salesperson: add their name, then create their tab
C25: • Monthly target is referenced by every personal tab dashboard
C26: • Do NOT rename this sheet — formulas depend on it

Sheet 📈 Summary Dashboard
A1: 📈 TEAM PIPELINE SUMMARY DASHBOARD
S3: Month | T3: Team Target | U3: Taken Orders (Deal Signed) | V3: Delivered Orders
A4: Total Pipeline (All Reps, THB) | E4: Weighted Pipeline (THB) | I4: Signed This Month (THB) | M4: Team Monthly Target (THB) | S4: Jan | T4: 15000000 | U4: =SUMPRODUCT(IFERROR((MONTH('👤 Mew'!L58:L228)=1)*(YEAR('👤 Mew'!L58:L228)=2026),0)*'👤 Mew'!I58:I228)+SUMPRODUCT(IFERROR((MONTH('👤 Napat'!L42:L144)=1)*(YEAR('👤 Napat'!L42:L144)=2026),0)*'👤 Napat'!I42:I144)+SUMPRODUCT(IFERROR((MONTH('👤 Tan'!L52:L151)=1)*(YEAR('👤 Tan'!L52:L151)=2026),0)*'👤 Tan'!I52:I151)+SUMPRODUCT(IFERROR((MONTH('👤 Aoey'!L42:L141)=1)*(YEAR('👤 Aoey'!L42:L141)=2026),0)*'👤 Aoey'!I42:I141)+SUMPRODUCT(IFERROR((MONTH('👤 Other Sales'!L42:L141)=1)*(YEAR('👤 Other Sales'!L42:L141)=2026),0)*'👤 Other Sales'!I42:I141) -> 0 | V4: =SUMPRODUCT(IFERROR((MONTH('👤 Mew'!M58:M228)=1)*(YEAR('👤 Mew'!M58:M228)=2026),0)*'👤 Mew'!I58:I228)+SUMPRODUCT(IFERROR((MONTH('👤 Napat'!M42:M144)=1)*(YEAR('👤 Napat'!M42:M144)=2026),0)*'👤 Napat'!I42:I144)+SUMPRODUCT(IFERROR((MONTH('👤 Tan'!M52:M151)=1)*(YEAR('👤 Tan'!M52:M151)=2026),0)*'👤 Tan'!I52:I151)+SUMPRODUCT(IFERROR((MONTH('👤 Aoey'!M42:M141)=1)*(YEAR('👤 Aoey'!M42:M141)=2026),0)*'👤 Aoey'!I42:I141)+SUMPRODUCT(IFERROR((MONTH('👤 Other Sales'!M42:M141)=1)*(YEAR('👤 Other Sales'!M42:M141)=2026),0)*'👤 Other Sales'!I42:I141) -> 0
A5: =SUMIF('👤 Mew'!B42:B228,"<>Delivered",'👤 Mew'!I58:I228)+SUMIF('👤 Napat'!B42:B144,"<>Delivered",'👤 Napat'!I42:I144)+SUMIF('👤 Tan'!B52:B151,"<>Delivered",'👤 Tan'!I52:I151)+SUMIF('👤 Aoey'!B42:B141,"<>Delivered",'👤 Aoey'!I42:I141)+SUMIF('👤 Other Sales'!B42:B141,"<>Delivered",'👤 Other Sales'!I42:I141) -> 68955469 | E5: =SUM('👤 Mew'!K42:K228)+SUM('👤 Napat'!K42:K144)+SUM('👤 Tan'!K52:K151)+SUM('👤 Aoey'!K42:K141)+SUM('👤 Other Sales'!K42:K141) -> 95155474 | I5: =SUMPRODUCT(('👤 Mew'!B42:B228="Deal Signed")*IFERROR((MONTH('👤 Mew'!L42:L228)=MONTH(TODAY()))*(YEAR('👤 Mew'!L42:L228)=YEAR(TODAY())),0)*'👤 Mew'!I42:I228)+SUMPRODUCT(('👤 Mew'!B42:B228="Delivered")*IFERROR((MONTH('👤 Mew'!L42:L228)=MONTH(TODAY()))*(YEAR('👤 Mew'!L42:L228)=YEAR(TODAY())),0)*'👤 Mew'!I42:I228)+SUMPRODUCT(('👤 Napat'!B42:B144="Deal Signed")*IFERROR((MONTH('👤 Napat'!L42:L144)=MONTH(TODAY()))*(YEAR('👤 Napat'!L42:L144)=YEAR(TODAY())),0)*'👤 Napat'!I42:I144)+SUMPRODUCT(('👤 Napat'!B42:B144="Delivered")*IFERROR((MONTH('👤 Napat'!L42:L144)=MONTH(TODAY()))*(YEAR('👤 Napat'!L42:L144)=YEAR(TODAY())),0)*'👤 Napat'!I42:I144)+SUMPRODUCT(('👤 Tan'!B52:B151="Deal Signed")*IFERROR((MONTH('👤 Tan'!L52:L151)=MONTH(TODAY()))*(YEAR('👤 Tan'!L52:L151)=YEAR(TODAY())),0)*'👤 Tan'!I52:I151)+SUMPRODUCT(('👤 Tan'!B52:B151="Delivered")*IFERROR((MONTH('👤 Tan'!L52:L151)=MONTH(TODAY()))*(YEAR('👤 Tan'!L52:L151)=YEAR(TODAY())),0)*'👤 Tan'!I52:I151)+SUMPRODUCT(('👤 Aoey'!B42:B141="Deal Signed")*IFERROR((MONTH('👤 Aoey'!L42:L141)=MONTH(TODAY()))*(YEAR('👤 Aoey'!L42:L141)=YEAR(TODAY())),0)*'👤 Aoey'!I42:I141)+SUMPRODUCT(('👤 Aoey'!B42:B141="Delivered")*IFERROR((MONTH('👤 Aoey'!L42:L141)=MONTH(TODAY()))*(YEAR('👤 Aoey'!L42:L141)=YEAR(TODAY())),0)*'👤 Aoey'!I42:I141)+SUMPRODUCT(('👤 Other Sales'!B42:B141="Deal Signed")*IFERROR((MONTH('👤 Other Sales'!L42:L141)=MONTH(TODAY()))*(YEAR('👤 Other Sales'!L42:L141)=YEAR(TODAY())),0)*'👤 Other Sales'!I42:I141)+SUMPRODUCT(('👤 Other Sales'!B42:B141="Delivered")*IFERROR((MONTH('👤 Other Sales'!L42:L141)=MONTH(TODAY()))*(YEAR('👤 Other Sales'!L42:L141)=YEAR(TODAY())),0)*'👤 Other Sales'!I42:I141) -> 0 | M5: =SUM(E11:E15) -> 12000000 | S5: Feb | T5: 15000000 | U5: =SUMPRODUCT(IFERROR((MONTH('👤 Mew'!L58:L228)=2)*(YEAR('👤 Mew'!L58:L228)=2026),0)*'👤 Mew'!I58:I228)+SUMPRODUCT(IFERROR((MONTH('👤 Napat'!L42:L144)=2)*(YEAR('👤 Napat'!L42:L144)=2026),0)*'👤 Napat'!I42:I144)+SUMPRODUCT(IFERROR((MONTH('👤 Tan'!L52:L151)=2)*(YEAR('👤 Tan'!L52:L151)=2026),0)*'👤 Tan'!I52:I151)+SUMPRODUCT(IFERROR((MONTH('👤 Aoey'!L42:L141)=2)*(YEAR('👤 Aoey'!L42:L141)=2026),0)*'👤 Aoey'!I42:I141)+SUMPRODUCT(IFERROR((MONTH('👤 Other Sales'!L42:L141)=2)*(YEAR('👤 Other Sales'!L42:L141)=2026),0)*'👤 Other Sales'!I42:I141) -> 0 | V5: =SUMPRODUCT(IFERROR((MONTH('👤 Mew'!M58:M228)=2)*(YEAR('👤 Mew'!M58:M228)=2026),0)*'👤 Mew'!I58:I228)+SUMPRODUCT(IFERROR((MONTH('👤 Napat'!M42:M144)=2)*(YEAR('👤 Napat'!M42:M144)=2026),0)*'👤 Napat'!I42:I144)+SUMPRODUCT(IFERROR((MONTH('👤 Tan'!M52:M151)=2)*(YEAR('👤 Tan'!M52:M151)=2026),0)*'👤 Tan'!I52:I151)+SUMPRODUCT(IFERROR((MONTH('👤 Aoey'!M42:M141)=2)*(YEAR('👤 Aoey'!M42:M141)=2026),0)*'👤 Aoey'!I42:I141)+SUMPRODUCT(IFERROR((MONTH('👤 Other Sales'!M42:M141)=2)*(YEAR('👤 Other Sales'!M42:M141)=2026),0)*'👤 Other Sales'!I42:I141) -> 0
S6: Mar | T6: 15000000 | U6: =SUMPRODUCT(IFERROR((MONTH('👤 Mew'!L58:L228)=3)*(YEAR('👤 Mew'!L58:L228)=2026),0)*'👤 Mew'!I58:I228)+SUMPRODUCT(IFERROR((MONTH('👤 Napat'!L42:L144)=3)*(YEAR('👤 Napat'!L42:L144)=2026),0)*'👤 Napat'!I42:I144)+SUMPRODUCT(IFERROR((MONTH('👤 Tan'!L52:L151)=3)*(YEAR('👤 Tan'!L52:L151)=2026),0)*'👤 Tan'!I52:I151)+SUMPRODUCT(IFERROR((MONTH('👤 Aoey'!L42:L141)=3)*(YEAR('👤 Aoey'!L42:L141)=2026),0)*'👤 Aoey'!I42:I141)+SUMPRODUCT(IFERROR((MONTH('👤 Other Sales'!L42:L141)=3)*(YEAR('👤 Other Sales'!L42:L141)=2026),0)*'👤 Other Sales'!I42:I141) -> 0 | V6: =SUMPRODUCT(IFERROR((MONTH('👤 Mew'!M58:M228)=3)*(YEAR('👤 Mew'!M58:M228)=2026),0)*'👤 Mew'!I58:I228)+SUMPRODUCT(IFERROR((MONTH('👤 Napat'!M42:M144)=3)*(YEAR('👤 Napat'!M42:M144)=2026),0)*'👤 Napat'!I42:I144)+SUMPRODUCT(IFERROR((MONTH('👤 Tan'!M52:M151)=3)*(YEAR('👤 Tan'!M52:M151)=2026),0)*'👤 Tan'!I52:I151)+SUMPRODUCT(IFERROR((MONTH('👤 Aoey'!M42:M141)=3)*(YEAR('👤 Aoey'!M42:M141)=2026),0)*'👤 Aoey'!I42:I141)+SUMPRODUCT(IFERROR((MONTH('👤 Other Sales'!M42:M141)=3)*(YEAR('👤 Other Sales'!M42:M141)=2026),0)*'👤 Other Sales'!I42:I141) -> 0
S7: Apr | T7: 15000000 | U7: =SUMPRODUCT(IFERROR((MONTH('👤 Mew'!L58:L228)=4)*(YEAR('👤 Mew'!L58:L228)=2026),0)*'👤 Mew'!I58:I228)+SUMPRODUCT(IFERROR((MONTH('👤 Napat'!L42:L144)=4)*(YEAR('👤 Napat'!L42:L144)=2026),0)*'👤 Napat'!I42:I144)+SUMPRODUCT(IFERROR((MONTH('👤 Tan'!L52:L151)=4)*(YEAR('👤 Tan'!L52:L151)=2026),0)*'👤 Tan'!I52:I151)+SUMPRODUCT(IFERROR((MONTH('👤 Aoey'!L42:L141)=4)*(YEAR('👤 Aoey'!L42:L141)=2026),0)*'👤 Aoey'!I42:I141)+SUMPRODUCT(IFERROR((MONTH('👤 Other Sales'!L42:L141)=4)*(YEAR('👤 Other Sales'!L42:L141)=2026),0)*'👤 Other Sales'!I42:I141) -> 0 | V7: =SUMPRODUCT(IFERROR((MONTH('👤 Mew'!M58:M228)=4)*(YEAR('👤 Mew'!M58:M228)=2026),0)*'👤 Mew'!I58:I228)+SUMPRODUCT(IFERROR((MONTH('👤 Napat'!M42:M144)=4)*(YEAR('👤 Napat'!M42:M144)=2026),0)*'👤 Napat'!I42:I144)+SUMPRODUCT(IFERROR((MONTH('👤 Tan'!M52:M151)=4)*(YEAR('👤 Tan'!M52:M151)=2026),0)*'👤 Tan'!I52:I151)+SUMPRODUCT(IFERROR((MONTH('👤 Aoey'!M42:M141)=4)*(YEAR('👤 Aoey'!M42:M141)=2026),0)*'👤 Aoey'!I42:I141)+SUMPRODUCT(IFERROR((MONTH('👤 Other Sales'!M42:M141)=4)*(YEAR('👤 Other Sales'!M42:M141)=2026),0)*'👤 Other Sales'!I42:I141) -> 0
S8: May | T8: 15000000 | U8: =SUMPRODUCT(IFERROR((MONTH('👤 Mew'!L58:L228)=5)*(YEAR('👤 Mew'!L58:L228)=2026),0)*'👤 Mew'!I58:I228)+SUMPRODUCT(IFERROR((MONTH('👤 Napat'!L42:L144)=5)*(YEAR('👤 Napat'!L42:L144)=2026),0)*'👤 Napat'!I42:I144)+SUMPRODUCT(IFERROR((MONTH('👤 Tan'!L52:L151)=5)*(YEAR('👤 Tan'!L52:L151)=2026),0)*'👤 Tan'!I52:I151)+SUMPRODUCT(IFERROR((MONTH('👤 Aoey'!L42:L141)=5)*(YEAR('👤 Aoey'!L42:L141)=2026),0)*'👤 Aoey'!I42:I141)+SUMPRODUCT(IFERROR((MONTH('👤 Other Sales'!L42:L141)=5)*(YEAR('👤 Other Sales'!L42:L141)=2026),0)*'👤 Other Sales'!I42:I141) -> 0 | V8: =SUMPRODUCT(IFERROR((MONTH('👤 Mew'!M58:M228)=5)*(YEAR('👤 Mew'!M58:M228)=2026),0)*'👤 Mew'!I58:I228)+SUMPRODUCT(IFERROR((MONTH('👤 Napat'!M42:M144)=5)*(YEAR('👤 Napat'!M42:M144)=2026),0)*'👤 Napat'!I42:I144)+SUMPRODUCT(IFERROR((MONTH('👤 Tan'!M52:M151)=5)*(YEAR('👤 Tan'!M52:M151)=2026),0)*'👤 Tan'!I52:I151)+SUMPRODUCT(IFERROR((MONTH('👤 Aoey'!M42:M141)=5)*(YEAR('👤 Aoey'!M42:M141)=2026),0)*'👤 Aoey'!I42:I141)+SUMPRODUCT(IFERROR((MONTH('👤 Other Sales'!M42:M141)=5)*(YEAR('👤 Other Sales'!M42:M141)=2026),0)*'👤 Other Sales'!I42:I141) -> 0
A9: 🏆 Performance by Salesperson | S9: Jun | T9: 15000000 | U9: =SUMPRODUCT(IFERROR((MONTH('👤 Mew'!L58:L228)=6)*(YEAR('👤 Mew'!L58:L228)=2026),0)*'👤 Mew'!I58:I228)+SUMPRODUCT(IFERROR((MONTH('👤 Napat'!L42:L144)=6)*(YEAR('👤 Napat'!L42:L144)=2026),0)*'👤 Napat'!I42:I144)+SUMPRODUCT(IFERROR((MONTH('👤 Tan'!L52:L151)=6)*(YEAR('👤 Tan'!L52:L151)=2026),0)*'👤 Tan'!I52:I151)+SUMPRODUCT(IFERROR((MONTH('👤 Aoey'!L42:L141)=6)*(YEAR('👤 Aoey'!L42:L141)=2026),0)*'👤 Aoey'!I42:I141)+SUMPRODUCT(IFERROR((MONTH('👤 Other Sales'!L42:L141)=6)*(YEAR('👤 Other Sales'!L42:L141)=2026),0)*'👤 Other Sales'!I42:I141) -> 0 | V9: =SUMPRODUCT(IFERROR((MONTH('👤 Mew'!M58:M228)=6)*(YEAR('👤 Mew'!M58:M228)=2026),0)*'👤 Mew'!I58:I228)+SUMPRODUCT(IFERROR((MONTH('👤 Napat'!M42:M144)=6)*(YEAR('👤 Napat'!M42:M144)=2026),0)*'👤 Napat'!I42:I144)+SUMPRODUCT(IFERROR((MONTH('👤 Tan'!M52:M151)=6)*(YEAR('👤 Tan'!M52:M151)=2026),0)*'👤 Tan'!I52:I151)+SUMPRODUCT(IFERROR((MONTH('👤 Aoey'!M42:M141)=6)*(YEAR('👤 Aoey'!M42:M141)=2026),0)*'👤 Aoey'!I42:I141)+SUMPRODUCT(IFERROR((MONTH('👤 Other Sales'!M42:M141)=6)*(YEAR('👤 Other Sales'!M42:M141)=2026),0)*'👤 Other Sales'!I42:I141) -> 0
A10: Salesperson | B10: Total Pipeline (THB) | C10: Weighted (THB) | D10: Signed MTD (THB) | E10: Target (THB) | F10: Progress | G10: High Priority | H10: In Negotiating | I10: In Deal Signed | J10: In Delivered | S10: Jul | T10: 15000000 | U10: =SUMPRODUCT(IFERROR((MONTH('👤 Mew'!L58:L228)=7)*(YEAR('👤 Mew'!L58:L228)=2026),0)*'👤 Mew'!I58:I228)+SUMPRODUCT(IFERROR((MONTH('👤 Napat'!L42:L144)=7)*(YEAR('👤 Napat'!L42:L144)=2026),0)*'👤 Napat'!I42:I144)+SUMPRODUCT(IFERROR((MONTH('👤 Tan'!L52:L151)=7)*(YEAR('👤 Tan'!L52:L151)=2026),0)*'👤 Tan'!I52:I151)+SUMPRODUCT(IFERROR((MONTH('👤 Aoey'!L42:L141)=7)*(YEAR('👤 Aoey'!L42:L141)=2026),0)*'👤 Aoey'!I42:I141)+SUMPRODUCT(IFERROR((MONTH('👤 Other Sales'!L42:L141)=7)*(YEAR('👤 Other Sales'!L42:L141)=2026),0)*'👤 Other Sales'!I42:I141) -> 0 | V10: =SUMPRODUCT(IFERROR((MONTH('👤 Mew'!M58:M228)=7)*(YEAR('👤 Mew'!M58:M228)=2026),0)*'👤 Mew'!I58:I228)+SUMPRODUCT(IFERROR((MONTH('👤 Napat'!M42:M144)=7)*(YEAR('👤 Napat'!M42:M144)=2026),0)*'👤 Napat'!I42:I144)+SUMPRODUCT(IFERROR((MONTH('👤 Tan'!M52:M151)=7)*(YEAR('👤 Tan'!M52:M151)=2026),0)*'👤 Tan'!I52:I151)+SUMPRODUCT(IFERROR((MONTH('👤 Aoey'!M42:M141)=7)*(YEAR('👤 Aoey'!M42:M141)=2026),0)*'👤 Aoey'!I42:I141)+SUMPRODUCT(IFERROR((MONTH('👤 Other Sales'!M42:M141)=7)*(YEAR('👤 Other Sales'!M42:M141)=2026),0)*'👤 Other Sales'!I42:I141) -> 0
A11: Mew | B11: =SUMIF('👤 Mew'!B42:B228,"<>Delivered",'👤 Mew'!I42:I228) -> 8725490 | C11: =SUM('👤 Mew'!K42:K228) -> 33968159 | D11: =SUMPRODUCT(('👤 Mew'!B42:B228="Deal Signed")*IFERROR((MONTH('👤 Mew'!L42:L228)=MONTH(TODAY()))*(YEAR('👤 Mew'!L42:L228)=YEAR(TODAY())),0)*'👤 Mew'!I42:I228)+SUMPRODUCT(('👤 Mew'!B42:B228="Delivered")*IFERROR((MONTH('👤 Mew'!L42:L228)=MONTH(TODAY()))*(YEAR('👤 Mew'!L42:L228)=YEAR(TODAY())),0)*'👤 Mew'!I42:I228) -> 0 | E11: ='⚙ Control Panel'!$A$23 -> 3000000 | F11: =IFERROR(D11/E11,0) -> 0 | G11: =COUNTIF('👤 Mew'!D42:D228,"High") -> 25 | H11: =COUNTIF('👤 Mew'!B58:B228,"Negotiating") -> 0 | I11: =COUNTIF('👤 Mew'!B42:B228,"Deal Signed") -> 16 | J11: =COUNTIF('👤 Mew'!B42:B228,"Delivered") -> 99 | S11: Aug | T11: 15000000 | U11: =SUMPRODUCT(IFERROR((MONTH('👤 Mew'!L58:L228)=8)*(YEAR('👤 Mew'!L58:L228)=2026),0)*'👤 Mew'!I58:I228)+SUMPRODUCT(IFERROR((MONTH('👤 Napat'!L42:L144)=8)*(YEAR('👤 Napat'!L42:L144)=2026),0)*'👤 Napat'!I42:I144)+SUMPRODUCT(IFERROR((MONTH('👤 Tan'!L52:L151)=8)*(YEAR('👤 Tan'!L52:L151)=2026),0)*'👤 Tan'!I52:I151)+SUMPRODUCT(IFERROR((MONTH('👤 Aoey'!L42:L141)=8)*(YEAR('👤 Aoey'!L42:L141)=2026),0)*'👤 Aoey'!I42:I141)+SUMPRODUCT(IFERROR((MONTH('👤 Other Sales'!L42:L141)=8)*(YEAR('👤 Other Sales'!L42:L141)=2026),0)*'👤 Other Sales'!I42:I141) -> 0 | V11: =SUMPRODUCT(IFERROR((MONTH('👤 Mew'!M58:M228)=8)*(YEAR('👤 Mew'!M58:M228)=2026),0)*'👤 Mew'!I58:I228)+SUMPRODUCT(IFERROR((MONTH('👤 Napat'!M42:M144)=8)*(YEAR('👤 Napat'!M42:M144)=2026),0)*'👤 Napat'!I42:I144)+SUMPRODUCT(IFERROR((MONTH('👤 Tan'!M52:M151)=8)*(YEAR('👤 Tan'!M52:M151)=2026),0)*'👤 Tan'!I52:I151)+SUMPRODUCT(IFERROR((MONTH('👤 Aoey'!M42:M141)=8)*(YEAR('👤 Aoey'!M42:M141)=2026),0)*'👤 Aoey'!I42:I141)+SUMPRODUCT(IFERROR((MONTH('👤 Other Sales'!M42:M141)=8)*(YEAR('👤 Other Sales'!M42:M141)=2026),0)*'👤 Other Sales'!I42:I141) -> 0
A12: Napat | B12: =SUMIF('👤 Napat'!B42:B144,"<>Delivered",'👤 Napat'!I42:I144) -> 15480135 | C12: =SUM('👤 Napat'!K42:K144) -> 11678202 | D12: =SUMPRODUCT(('👤 Napat'!B42:B144="Deal Signed")*IFERROR((MONTH('👤 Napat'!L42:L144)=MONTH(TODAY()))*(YEAR('👤 Napat'!L42:L144)=YEAR(TODAY())),0)*'👤 Napat'!I42:I144)+SUMPRODUCT(('👤 Napat'!B42:B144="Delivered")*IFERROR((MONTH('👤 Napat'!L42:L144)=MONTH(TODAY()))*(YEAR('👤 Napat'!L42:L144)=YEAR(TODAY())),0)*'👤 Napat'!I42:I144) -> 0 | E12: ='⚙ Control Panel'!$A$23 -> 3000000 | F12: =IFERROR(D12/E12,0) -> 0 | G12: =COUNTIF('👤 Napat'!D42:D144,"High") -> 9 | H12: =COUNTIF('👤 Napat'!B42:B144,"Negotiating") -> 0 | I12: =COUNTIF('👤 Napat'!B42:B144,"Deal Signed") -> 0 | J12: =COUNTIF('👤 Napat'!B42:B144,"Delivered") -> 7 | S12: Sep | T12: 15000000 | U12: =SUMPRODUCT(IFERROR((MONTH('👤 Mew'!L58:L228)=9)*(YEAR('👤 Mew'!L58:L228)=2026),0)*'👤 Mew'!I58:I228)+SUMPRODUCT(IFERROR((MONTH('👤 Napat'!L42:L144)=9)*(YEAR('👤 Napat'!L42:L144)=2026),0)*'👤 Napat'!I42:I144)+SUMPRODUCT(IFERROR((MONTH('👤 Tan'!L52:L151)=9)*(YEAR('👤 Tan'!L52:L151)=2026),0)*'👤 Tan'!I52:I151)+SUMPRODUCT(IFERROR((MONTH('👤 Aoey'!L42:L141)=9)*(YEAR('👤 Aoey'!L42:L141)=2026),0)*'👤 Aoey'!I42:I141)+SUMPRODUCT(IFERROR((MONTH('👤 Other Sales'!L42:L141)=9)*(YEAR('👤 Other Sales'!L42:L141)=2026),0)*'👤 Other Sales'!I42:I141) -> 0 | V12: =SUMPRODUCT(IFERROR((MONTH('👤 Mew'!M58:M228)=9)*(YEAR('👤 Mew'!M58:M228)=2026),0)*'👤 Mew'!I58:I228)+SUMPRODUCT(IFERROR((MONTH('👤 Napat'!M42:M144)=9)*(YEAR('👤 Napat'!M42:M144)=2026),0)*'👤 Napat'!I42:I144)+SUMPRODUCT(IFERROR((MONTH('👤 Tan'!M52:M151)=9)*(YEAR('👤 Tan'!M52:M151)=2026),0)*'👤 Tan'!I52:I151)+SUMPRODUCT(IFERROR((MONTH('👤 Aoey'!M42:M141)=9)*(YEAR('👤 Aoey'!M42:M141)=2026),0)*'👤 Aoey'!I42:I141)+SUMPRODUCT(IFERROR((MONTH('👤 Other Sales'!M42:M141)=9)*(YEAR('👤 Other Sales'!M42:M141)=2026),0)*'👤 Other Sales'!I42:I141) -> 0
A13: Tan | B13: =SUMIF('👤 Tan'!B52:B151,"<>Delivered",'👤 Tan'!I52:I151) -> 50605750 | C13: =SUM('👤 Tan'!K52:K151) -> 48716158 | D13: =SUMPRODUCT(('👤 Tan'!B52:B151="Deal Signed")*IFERROR((MONTH('👤 Tan'!L52:L151)=MONTH(TODAY()))*(YEAR('👤 Tan'!L52:L151)=YEAR(TODAY())),0)*'👤 Tan'!I52:I151)+SUMPRODUCT(('👤 Tan'!B52:B151="Delivered")*IFERROR((MONTH('👤 Tan'!L52:L151)=MONTH(TODAY()))*(YEAR('👤 Tan'!L52:L151)=YEAR(TODAY())),0)*'👤 Tan'!I52:I151) -> 0 | E13: ='⚙ Control Panel'!$A$23 -> 3000000 | F13: =IFERROR(D13/E13,0) -> 0 | G13: =COUNTIF('👤 Tan'!D52:D151,"High") -> 14 | H13: =COUNTIF('👤 Tan'!B52:B151,"Negotiating") -> 3 | I13: =COUNTIF('👤 Tan'!B52:B151,"Deal Signed") -> 7 | J13: =COUNTIF('👤 Tan'!B52:B151,"Delivered") -> 0 | S13: Oct | T13: 15000000 | U13: =SUMPRODUCT(IFERROR((MONTH('👤 Mew'!L58:L228)=10)*(YEAR('👤 Mew'!L58:L228)=2026),0)*'👤 Mew'!I58:I228)+SUMPRODUCT(IFERROR((MONTH('👤 Napat'!L42:L144)=10)*(YEAR('👤 Napat'!L42:L144)=2026),0)*'👤 Napat'!I42:I144)+SUMPRODUCT(IFERROR((MONTH('👤 Tan'!L52:L151)=10)*(YEAR('👤 Tan'!L52:L151)=2026),0)*'👤 Tan'!I52:I151)+SUMPRODUCT(IFERROR((MONTH('👤 Aoey'!L42:L141)=10)*(YEAR('👤 Aoey'!L42:L141)=2026),0)*'👤 Aoey'!I42:I141)+SUMPRODUCT(IFERROR((MONTH('👤 Other Sales'!L42:L141)=10)*(YEAR('👤 Other Sales'!L42:L141)=2026),0)*'👤 Other Sales'!I42:I141) -> 0 | V13: =SUMPRODUCT(IFERROR((MONTH('👤 Mew'!M58:M228)=10)*(YEAR('👤 Mew'!M58:M228)=2026),0)*'👤 Mew'!I58:I228)+SUMPRODUCT(IFERROR((MONTH('👤 Napat'!M42:M144)=10)*(YEAR('👤 Napat'!M42:M144)=2026),0)*'👤 Napat'!I42:I144)+SUMPRODUCT(IFERROR((MONTH('👤 Tan'!M52:M151)=10)*(YEAR('👤 Tan'!M52:M151)=2026),0)*'👤 Tan'!I52:I151)+SUMPRODUCT(IFERROR((MONTH('👤 Aoey'!M42:M141)=10)*(YEAR('👤 Aoey'!M42:M141)=2026),0)*'👤 Aoey'!I42:I141)+SUMPRODUCT(IFERROR((MONTH('👤 Other Sales'!M42:M141)=10)*(YEAR('👤 Other Sales'!M42:M141)=2026),0)*'👤 Other Sales'!I42:I141) -> 0
A14: Aoey | B14: =SUMIF('👤 Aoey'!B42:B141,"<>Delivered",'👤 Aoey'!I42:I141) -> 0 | C14: =SUM('👤 Aoey'!K42:K141) -> 792955 | D14: =SUMPRODUCT(('👤 Aoey'!B42:B141="Deal Signed")*IFERROR((MONTH('👤 Aoey'!L42:L141)=MONTH(TODAY()))*(YEAR('👤 Aoey'!L42:L141)=YEAR(TODAY())),0)*'👤 Aoey'!I42:I141)+SUMPRODUCT(('👤 Aoey'!B42:B141="Delivered")*IFERROR((MONTH('👤 Aoey'!L42:L141)=MONTH(TODAY()))*(YEAR('👤 Aoey'!L42:L141)=YEAR(TODAY())),0)*'👤 Aoey'!I42:I141) -> 0 | E14: ='⚙ Control Panel'!$A$23 -> 3000000 | F14: =IFERROR(D14/E14,0) -> 0 | G14: =COUNTIF('👤 Aoey'!D42:D141,"High") -> 8 | H14: =COUNTIF('👤 Aoey'!B42:B141,"Negotiating") -> 0 | I14: =COUNTIF('👤 Aoey'!B42:B141,"Deal Signed") -> 0 | J14: =COUNTIF('👤 Aoey'!B42:B141,"Delivered") -> 8 | S14: Nov | T14: 15000000 | U14: =SUMPRODUCT(IFERROR((MONTH('👤 Mew'!L58:L228)=11)*(YEAR('👤 Mew'!L58:L228)=2026),0)*'👤 Mew'!I58:I228)+SUMPRODUCT(IFERROR((MONTH('👤 Napat'!L42:L144)=11)*(YEAR('👤 Napat'!L42:L144)=2026),0)*'👤 Napat'!I42:I144)+SUMPRODUCT(IFERROR((MONTH('👤 Tan'!L52:L151)=11)*(YEAR('👤 Tan'!L52:L151)=2026),0)*'👤 Tan'!I52:I151)+SUMPRODUCT(IFERROR((MONTH('👤 Aoey'!L42:L141)=11)*(YEAR('👤 Aoey'!L42:L141)=2026),0)*'👤 Aoey'!I42:I141)+SUMPRODUCT(IFERROR((MONTH('👤 Other Sales'!L42:L141)=11)*(YEAR('👤 Other Sales'!L42:L141)=2026),0)*'👤 Other Sales'!I42:I141) -> 0 | V14: =SUMPRODUCT(IFERROR((MONTH('👤 Mew'!M58:M228)=11)*(YEAR('👤 Mew'!M58:M228)=2026),0)*'👤 Mew'!I58:I228)+SUMPRODUCT(IFERROR((MONTH('👤 Napat'!M42:M144)=11)*(YEAR('👤 Napat'!M42:M144)=2026),0)*'👤 Napat'!I42:I144)+SUMPRODUCT(IFERROR((MONTH('👤 Tan'!M52:M151)=11)*(YEAR('👤 Tan'!M52:M151)=2026),0)*'👤 Tan'!I52:I151)+SUMPRODUCT(IFERROR((MONTH('👤 Aoey'!M42:M141)=11)*(YEAR('👤 Aoey'!M42:M141)=2026),0)*'👤 Aoey'!I42:I141)+SUMPRODUCT(IFERROR((MONTH('👤 Other Sales'!M42:M141)=11)*(YEAR('👤 Other Sales'!M42:M141)=2026),0)*'👤 Other Sales'!I42:I141) -> 0
A15: Other Sales | B15: =SUMIF('👤 Other Sales'!B42:B141,"<>Delivered",'👤 Other Sales'!I42:I141) -> 0 | C15: =SUM('👤 Other Sales'!K42:K141) -> 0 | D15: =SUMPRODUCT(('👤 Other Sales'!B42:B141="Deal Signed")*IFERROR((MONTH('👤 Other Sales'!L42:L141)=MONTH(TODAY()))*(YEAR('👤 Other Sales'!L42:L141)=YEAR(TODAY())),0)*'👤 Other Sales'!I42:I141)+SUMPRODUCT(('👤 Other Sales'!B42:B141="Delivered")*IFERROR((MONTH('👤 Other Sales'!L42:L141)=MONTH(TODAY()))*(YEAR('👤 Other Sales'!L42:L141)=YEAR(TODAY())),0)*'👤 Other Sales'!I42:I141) -> 0 | E15: 0 | F15: =IFERROR(D15/E15,0) -> 0 | G15: =COUNTIF('👤 Other Sales'!D42:D141,"High") -> 0 | H15: =COUNTIF('👤 Other Sales'!B42:B141,"Negotiating") -> 0 | I15: =COUNTIF('👤 Other Sales'!B42:B141,"Deal Signed") -> 0 | J15: =COUNTIF('👤 Other Sales'!B42:B141,"Delivered") -> 0 | S15: Dec | T15: 15000000 | U15: =SUMPRODUCT(IFERROR((MONTH('👤 Mew'!L58:L228)=12)*(YEAR('👤 Mew'!L58:L228)=2026),0)*'👤 Mew'!I58:I228)+SUMPRODUCT(IFERROR((MONTH('👤 Napat'!L42:L144)=12)*(YEAR('👤 Napat'!L42:L144)=2026),0)*'👤 Napat'!I42:I144)+SUMPRODUCT(IFERROR((MONTH('👤 Tan'!L52:L151)=12)*(YEAR('👤 Tan'!L52:L151)=2026),0)*'👤 Tan'!I52:I151)+SUMPRODUCT(IFERROR((MONTH('👤 Aoey'!L42:L141)=12)*(YEAR('👤 Aoey'!L42:L141)=2026),0)*'👤 Aoey'!I42:I141)+SUMPRODUCT(IFERROR((MONTH('👤 Other Sales'!L42:L141)=12)*(YEAR('👤 Other Sales'!L42:L141)=2026),0)*'👤 Other Sales'!I42:I141) -> 0 | V15: =SUMPRODUCT(IFERROR((MONTH('👤 Mew'!M58:M228)=12)*(YEAR('👤 Mew'!M58:M228)=2026),0)*'👤 Mew'!I58:I228)+SUMPRODUCT(IFERROR((MONTH('👤 Napat'!M42:M144)=12)*(YEAR('👤 Napat'!M42:M144)=2026),0)*'👤 Napat'!I42:I144)+SUMPRODUCT(IFERROR((MONTH('👤 Tan'!M52:M151)=12)*(YEAR('👤 Tan'!M52:M151)=2026),0)*'👤 Tan'!I52:I151)+SUMPRODUCT(IFERROR((MONTH('👤 Aoey'!M42:M141)=12)*(YEAR('👤 Aoey'!M42:M141)=2026),0)*'👤 Aoey'!I42:I141)+SUMPRODUCT(IFERROR((MONTH('👤 Other Sales'!M42:M141)=12)*(YEAR('👤 Other Sales'!M42:M141)=2026),0)*'👤 Other Sales'!I42:I141) -> 0
A16: TOTAL | B16: =SUM(B11:B15) -> 74811375 | C16: =SUM(C11:C15) -> 95155474 | D16: =SUM(D11:D15) -> 0 | E16: =SUM(E11:E15) -> 12000000 | F16: =IFERROR(D16/E16,0) -> 0 | G16: =SUM(G11:G15) -> 56 | H16: =SUM(H11:H15) -> 3 | I16: =SUM(I11:I15) -> 23 | J16: =SUM(J11:J15) -> 114
A17: 📈 TEAM MONTHLY SALES TREND — 2026
A41: 🔻 Pipeline by Stage (per Salesperson)
A42: Stage | B42: Mew | C42: Napat | D42: Tan | E42: Aoey | F42: Other Sales | G42: Total Deals | H42: Total Value (THB) | I42: % of Pipeline
A43: Interest | B43: =COUNTIF('👤 Mew'!B42:B228,"Interest") -> 5 | C43: =COUNTIF('👤 Napat'!B42:B144,"Interest") -> 2 | D43: =COUNTIF('👤 Tan'!B52:B151,"Interest") -> 2 | E43: =COUNTIF('👤 Aoey'!B42:B141,"Interest") -> 0 | F43: =COUNTIF('👤 Other Sales'!B42:B141,"Interest") -> 0 | G43: =SUM(B43:F43) -> 9 | H43: =SUMIF('👤 Mew'!B42:B228,"Interest",'👤 Mew'!I42:I228)+SUMIF('👤 Napat'!B42:B144,"Interest",'👤 Napat'!I42:I144)+SUMIF('👤 Tan'!B52:B151,"Interest",'👤 Tan'!I52:I151)+SUMIF('👤 Aoey'!B42:B141,"Interest",'👤 Aoey'!I42:I141)+SUMIF('👤 Other Sales'!B42:B141,"Interest",'👤 Other Sales'!I42:I141) -> 25252937 | I43: =IFERROR((SUMIF('👤 Mew'!B42:B228,"Interest",'👤 Mew'!I42:I228)+SUMIF('👤 Napat'!B42:B144,"Interest",'👤 Napat'!I42:I144)+SUMIF('👤 Tan'!B52:B151,"Interest",'👤 Tan'!I52:I151)+SUMIF('👤 Aoey'!B42:B141,"Interest",'👤 Aoey'!I42:I141)+SUMIF('👤 Other Sales'!B42:B141,"Interest",'👤 Other Sales'!I42:I141))/(SUM('👤 Mew'!I42:I228)+SUM('👤 Napat'!I42:I144)+SUM('👤 Tan'!I52:I151)+SUM('👤 Aoey'!I42:I141)+SUM('👤 Other Sales'!I42:I141)),0) -> 0.24561178
A44: Send PI | B44: =COUNTIF('👤 Mew'!B42:B228,"Send PI") -> 0 | C44: =COUNTIF('👤 Napat'!B42:B144,"Send PI") -> 0 | D44: =COUNTIF('👤 Tan'!B52:B151,"Send PI") -> 3 | E44: =COUNTIF('👤 Aoey'!B42:B141,"Send PI") -> 0 | F44: =COUNTIF('👤 Other Sales'!B42:B141,"Send PI") -> 0 | G44: =SUM(B44:F44) -> 3 | H44: =SUMIF('👤 Mew'!B42:B228,"Send PI",'👤 Mew'!I42:I228)+SUMIF('👤 Napat'!B42:B144,"Send PI",'👤 Napat'!I42:I144)+SUMIF('👤 Tan'!B52:B151,"Send PI",'👤 Tan'!I52:I151)+SUMIF('👤 Aoey'!B42:B141,"Send PI",'👤 Aoey'!I42:I141)+SUMIF('👤 Other Sales'!B42:B141,"Send PI",'👤 Other Sales'!I42:I141) -> 2332018 | I44: =IFERROR((SUMIF('👤 Mew'!B42:B228,"Send PI",'👤 Mew'!I42:I228)+SUMIF('👤 Napat'!B42:B144,"Send PI",'👤 Napat'!I42:I144)+SUMIF('👤 Tan'!B52:B151,"Send PI",'👤 Tan'!I52:I151)+SUMIF('👤 Aoey'!B42:B141,"Send PI",'👤 Aoey'!I42:I141)+SUMIF('👤 Other Sales'!B42:B141,"Send PI",'👤 Other Sales'!I42:I141))/(SUM('👤 Mew'!I42:I228)+SUM('👤 Napat'!I42:I144)+SUM('👤 Tan'!I52:I151)+SUM('👤 Aoey'!I42:I141)+SUM('👤 Other Sales'!I42:I141)),0) -> 0.022681365
A45: Negotiating | B45: =COUNTIF('👤 Mew'!B42:B228,"Negotiating") -> 0 | C45: =COUNTIF('👤 Napat'!B42:B144,"Negotiating") -> 0 | D45: =COUNTIF('👤 Tan'!B52:B151,"Negotiating") -> 3 | E45: =COUNTIF('👤 Aoey'!B42:B141,"Negotiating") -> 0 | F45: =COUNTIF('👤 Other Sales'!B42:B141,"Negotiating") -> 0 | G45: =SUM(B45:F45) -> 3 | H45: =SUMIF('👤 Mew'!B42:B228,"Negotiating",'👤 Mew'!I42:I228)+SUMIF('👤 Napat'!B42:B144,"Negotiating",'👤 Napat'!I42:I144)+SUMIF('👤 Tan'!B52:B151,"Negotiating",'👤 Tan'!I52:I151)+SUMIF('👤 Aoey'!B42:B141,"Negotiating",'👤 Aoey'!I42:I141)+SUMIF('👤 Other Sales'!B42:B141,"Negotiating",'👤 Other Sales'!I42:I141) -> 3082224 | I45: =IFERROR((SUMIF('👤 Mew'!B42:B228,"Negotiating",'👤 Mew'!I42:I228)+SUMIF('👤 Napat'!B42:B144,"Negotiating",'👤 Napat'!I42:I144)+SUMIF('👤 Tan'!B52:B151,"Negotiating",'👤 Tan'!I52:I151)+SUMIF('👤 Aoey'!B42:B141,"Negotiating",'👤 Aoey'!I42:I141)+SUMIF('👤 Other Sales'!B42:B141,"Negotiating",'👤 Other Sales'!I42:I141))/(SUM('👤 Mew'!I42:I228)+SUM('👤 Napat'!I42:I144)+SUM('👤 Tan'!I52:I151)+SUM('👤 Aoey'!I42:I141)+SUM('👤 Other Sales'!I42:I141)),0) -> 0.029977919
A46: Deal Signed | B46: =COUNTIF('👤 Mew'!B42:B228,"Deal Signed") -> 16 | C46: =COUNTIF('👤 Napat'!B42:B144,"Deal Signed") -> 0 | D46: =COUNTIF('👤 Tan'!B52:B151,"Deal Signed") -> 7 | E46: =COUNTIF('👤 Aoey'!B42:B141,"Deal Signed") -> 0 | F46: =COUNTIF('👤 Other Sales'!B42:B141,"Deal Signed") -> 0 | G46: =SUM(B46:F46) -> 23 | H46: =SUMIF('👤 Mew'!B42:B228,"Deal Signed",'👤 Mew'!I42:I228)+SUMIF('👤 Napat'!B42:B144,"Deal Signed",'👤 Napat'!I42:I144)+SUMIF('👤 Tan'!B52:B151,"Deal Signed",'👤 Tan'!I52:I151)+SUMIF('👤 Aoey'!B42:B141,"Deal Signed",'👤 Aoey'!I42:I141)+SUMIF('👤 Other Sales'!B42:B141,"Deal Signed",'👤 Other Sales'!I42:I141) -> 44118019 | I46: =IFERROR((SUMIF('👤 Mew'!B42:B228,"Deal Signed",'👤 Mew'!I42:I228)+SUMIF('👤 Napat'!B42:B144,"Deal Signed",'👤 Napat'!I42:I144)+SUMIF('👤 Tan'!B52:B151,"Deal Signed",'👤 Tan'!I52:I151)+SUMIF('👤 Aoey'!B42:B141,"Deal Signed",'👤 Aoey'!I42:I141)+SUMIF('👤 Other Sales'!B42:B141,"Deal Signed",'👤 Other Sales'!I42:I141))/(SUM('👤 Mew'!I42:I228)+SUM('👤 Napat'!I42:I144)+SUM('👤 Tan'!I52:I151)+SUM('👤 Aoey'!I42:I141)+SUM('👤 Other Sales'!I42:I141)),0) -> 0.42909484
A47: Delivered | B47: =COUNTIF('👤 Mew'!B42:B228,"Delivered") -> 99 | C47: =COUNTIF('👤 Napat'!B42:B144,"Delivered") -> 7 | D47: =COUNTIF('👤 Tan'!B52:B151,"Delivered") -> 0 | E47: =COUNTIF('👤 Aoey'!B42:B141,"Delivered") -> 8 | F47: =COUNTIF('👤 Other Sales'!B42:B141,"Delivered") -> 0 | G47: =SUM(B47:F47) -> 114 | H47: =SUMIF('👤 Mew'!B42:B228,"Delivered",'👤 Mew'!I42:I228)+SUMIF('👤 Napat'!B42:B144,"Delivered",'👤 Napat'!I42:I144)+SUMIF('👤 Tan'!B52:B151,"Delivered",'👤 Tan'!I52:I151)+SUMIF('👤 Aoey'!B42:B141,"Delivered",'👤 Aoey'!I42:I141)+SUMIF('👤 Other Sales'!B42:B141,"Delivered",'👤 Other Sales'!I42:I141) -> 28005100 | I47: =IFERROR((SUMIF('👤 Mew'!B42:B228,"Delivered",'👤 Mew'!I42:I228)+SUMIF('👤 Napat'!B42:B144,"Delivered",'👤 Napat'!I42:I144)+SUMIF('👤 Tan'!B52:B151,"Delivered",'👤 Tan'!I52:I151)+SUMIF('👤 Aoey'!B42:B141,"Delivered",'👤 Aoey'!I42:I141)+SUMIF('👤 Other Sales'!B42:B141,"Delivered",'👤 Other Sales'!I42:I141))/(SUM('👤 Mew'!I42:I228)+SUM('👤 Napat'!I42:I144)+SUM('👤 Tan'!I52:I151)+SUM('👤 Aoey'!I42:I141)+SUM('👤 Other Sales'!I42:I141)),0) -> 0.2723795
A48: Lost | B48: =COUNTIF('👤 Mew'!B42:B228,"Lost") -> 0 | C48: =COUNTIF('👤 Napat'!B42:B144,"Lost") -> 1 | D48: =COUNTIF('👤 Tan'!B52:B151,"Lost") -> 0 | E48: =COUNTIF('👤 Aoey'!B42:B141,"Lost") -> 0 | F48: =COUNTIF('👤 Other Sales'!B42:B141,"Lost") -> 0 | G48: =SUM(B48:F48) -> 1
A50: 📦 Pipeline by Product Category
A51: Category | B51: # Deals | C51: Value (THB) | D51: % Share
A52: Steel | B52: =COUNTIF('👤 Mew'!E42:E228,"Steel")+COUNTIF('👤 Napat'!E42:E144,"Steel")+COUNTIF('👤 Tan'!E52:E151,"Steel")+COUNTIF('👤 Aoey'!E42:E141,"Steel")+COUNTIF('👤 Other Sales'!E42:E141,"Steel") -> 42 | C52: =SUMIF('👤 Mew'!E42:E228,"Steel",'👤 Mew'!I42:I228)+SUMIF('👤 Napat'!E42:E144,"Steel",'👤 Napat'!I42:I144)+SUMIF('👤 Tan'!E52:E151,"Steel",'👤 Tan'!I52:I151)+SUMIF('👤 Aoey'!E42:E141,"Steel",'👤 Aoey'!I42:I141)+SUMIF('👤 Other Sales'!E42:E141,"Steel",'👤 Other Sales'!I42:I141) -> 22055506 | D52: =IFERROR((SUMIF('👤 Mew'!E42:E228,"Steel",'👤 Mew'!I42:I228)+SUMIF('👤 Napat'!E42:E144,"Steel",'👤 Napat'!I42:I144)+SUMIF('👤 Tan'!E52:E151,"Steel",'👤 Tan'!I52:I151)+SUMIF('👤 Aoey'!E42:E141,"Steel",'👤 Aoey'!I42:I141)+SUMIF('👤 Other Sales'!E42:E141,"Steel",'👤 Other Sales'!I42:I141))/(SUM('👤 Mew'!I42:I228)+SUM('👤 Napat'!I42:I144)+SUM('👤 Tan'!I52:I151)+SUM('👤 Aoey'!I42:I141)+SUM('👤 Other Sales'!I42:I141)),0) -> 0.21451335
A53: Chair | B53: =COUNTIF('👤 Mew'!E42:E228,"Chair")+COUNTIF('👤 Napat'!E42:E144,"Chair")+COUNTIF('👤 Tan'!E52:E151,"Chair")+COUNTIF('👤 Aoey'!E42:E141,"Chair")+COUNTIF('👤 Other Sales'!E42:E141,"Chair") -> 37 | C53: =SUMIF('👤 Mew'!E42:E228,"Chair",'👤 Mew'!I42:I228)+SUMIF('👤 Napat'!E42:E144,"Chair",'👤 Napat'!I42:I144)+SUMIF('👤 Tan'!E52:E151,"Chair",'👤 Tan'!I52:I151)+SUMIF('👤 Aoey'!E42:E141,"Chair",'👤 Aoey'!I42:I141)+SUMIF('👤 Other Sales'!E42:E141,"Chair",'👤 Other Sales'!I42:I141) -> 9306072 | D53: =IFERROR((SUMIF('👤 Mew'!E42:E228,"Chair",'👤 Mew'!I42:I228)+SUMIF('👤 Napat'!E42:E144,"Chair",'👤 Napat'!I42:I144)+SUMIF('👤 Tan'!E52:E151,"Chair",'👤 Tan'!I52:I151)+SUMIF('👤 Aoey'!E42:E141,"Chair",'👤 Aoey'!I42:I141)+SUMIF('👤 Other Sales'!E42:E141,"Chair",'👤 Other Sales'!I42:I141))/(SUM('👤 Mew'!I42:I228)+SUM('👤 Napat'!I42:I144)+SUM('👤 Tan'!I52:I151)+SUM('👤 Aoey'!I42:I141)+SUM('👤 Other Sales'!I42:I141)),0) -> 0.090511487
A54: Wooden | B54: =COUNTIF('👤 Mew'!E42:E228,"Wooden")+COUNTIF('👤 Napat'!E42:E144,"Wooden")+COUNTIF('👤 Tan'!E52:E151,"Wooden")+COUNTIF('👤 Aoey'!E42:E141,"Wooden")+COUNTIF('👤 Other Sales'!E42:E141,"Wooden") -> 71 | C54: =SUMIF('👤 Mew'!E42:E228,"Wooden",'👤 Mew'!I42:I228)+SUMIF('👤 Napat'!E42:E144,"Wooden",'👤 Napat'!I42:I144)+SUMIF('👤 Tan'!E52:E151,"Wooden",'👤 Tan'!I52:I151)+SUMIF('👤 Aoey'!E42:E141,"Wooden",'👤 Aoey'!I42:I141)+SUMIF('👤 Other Sales'!E42:E141,"Wooden",'👤 Other Sales'!I42:I141) -> 71426593 | D54: =IFERROR((SUMIF('👤 Mew'!E42:E228,"Wooden",'👤 Mew'!I42:I228)+SUMIF('👤 Napat'!E42:E144,"Wooden",'👤 Napat'!I42:I144)+SUMIF('👤 Tan'!E52:E151,"Wooden",'👤 Tan'!I52:I151)+SUMIF('👤 Aoey'!E42:E141,"Wooden",'👤 Aoey'!I42:I141)+SUMIF('👤 Other Sales'!E42:E141,"Wooden",'👤 Other Sales'!I42:I141))/(SUM('👤 Mew'!I42:I228)+SUM('👤 Napat'!I42:I144)+SUM('👤 Tan'!I52:I151)+SUM('👤 Aoey'!I42:I141)+SUM('👤 Other Sales'!I42:I141)),0) -> 0.69469988
A57: 🏷️ Pipeline by Brand
A58: Brand | B58: # Deals | C58: Value (THB) | D58: % Share
A59: Sunon | B59: =COUNTIF('👤 Mew'!F42:F228,"Sunon")+COUNTIF('👤 Napat'!F42:F144,"Sunon")+COUNTIF('👤 Tan'!F52:F151,"Sunon")+COUNTIF('👤 Aoey'!F42:F141,"Sunon")+COUNTIF('👤 Other Sales'!F42:F141,"Sunon") -> 7 | C59: =SUMIF('👤 Mew'!F42:F228,"Sunon",'👤 Mew'!I42:I228)+SUMIF('👤 Napat'!F42:F144,"Sunon",'👤 Napat'!I42:I144)+SUMIF('👤 Tan'!F52:F151,"Sunon",'👤 Tan'!I52:I151)+SUMIF('👤 Aoey'!F42:F141,"Sunon",'👤 Aoey'!I42:I141)+SUMIF('👤 Other Sales'!F42:F141,"Sunon",'👤 Other Sales'!I42:I141) -> 15843033 | D59: =IFERROR((SUMIF('👤 Mew'!F42:F228,"Sunon",'👤 Mew'!I42:I228)+SUMIF('👤 Napat'!F42:F144,"Sunon",'👤 Napat'!I42:I144)+SUMIF('👤 Tan'!F52:F151,"Sunon",'👤 Tan'!I52:I151)+SUMIF('👤 Aoey'!F42:F141,"Sunon",'👤 Aoey'!I42:I141)+SUMIF('👤 Other Sales'!F42:F141,"Sunon",'👤 Other Sales'!I42:I141))/(SUM('👤 Mew'!I42:I228)+SUM('👤 Napat'!I42:I144)+SUM('👤 Tan'!I52:I151)+SUM('👤 Aoey'!I42:I141)+SUM('👤 Other Sales'!I42:I141)),0) -> 0.15409041
A60: Taiyo | B60: =COUNTIF('👤 Mew'!F42:F228,"Taiyo")+COUNTIF('👤 Napat'!F42:F144,"Taiyo")+COUNTIF('👤 Tan'!F52:F151,"Taiyo")+COUNTIF('👤 Aoey'!F42:F141,"Taiyo")+COUNTIF('👤 Other Sales'!F42:F141,"Taiyo") -> 126 | C60: =SUMIF('👤 Mew'!F42:F228,"Taiyo",'👤 Mew'!I42:I228)+SUMIF('👤 Napat'!F42:F144,"Taiyo",'👤 Napat'!I42:I144)+SUMIF('👤 Tan'!F52:F151,"Taiyo",'👤 Tan'!I52:I151)+SUMIF('👤 Aoey'!F42:F141,"Taiyo",'👤 Aoey'!I42:I141)+SUMIF('👤 Other Sales'!F42:F141,"Taiyo",'👤 Other Sales'!I42:I141) -> 83331000 | D60: =IFERROR((SUMIF('👤 Mew'!F42:F228,"Taiyo",'👤 Mew'!I42:I228)+SUMIF('👤 Napat'!F42:F144,"Taiyo",'👤 Napat'!I42:I144)+SUMIF('👤 Tan'!F52:F151,"Taiyo",'👤 Tan'!I52:I151)+SUMIF('👤 Aoey'!F42:F141,"Taiyo",'👤 Aoey'!I42:I141)+SUMIF('👤 Other Sales'!F42:F141,"Taiyo",'👤 Other Sales'!I42:I141))/(SUM('👤 Mew'!I42:Y228)+SUM('👤 Napat'!I42:I144)+SUM('👤 Tan'!I52:I151)+SUM('👤 Aoey'!I42:I141)+SUM('👤 Other Sales'!I42:I141)),0) -> 0.55922853
A61: Motech | B61: =COUNTIF('👤 Mew'!F42:F228,"Motech")+COUNTIF('👤 Napat'!F42:F144,"Motech")+COUNTIF('👤 Tan'!F52:F151,"Motech")+COUNTIF('👤 Aoey'!F42:F141,"Motech")+COUNTIF('👤 Other Sales'!F42:F141,"Motech") -> 17 | C61: =SUMIF('👤 Mew'!F42:F228,"Motech",'👤 Mew'!I42:I228)+SUMIF('👤 Napat'!F42:F144,"Motech",'👤 Napat'!I42:I144)+SUMIF('👤 Tan'!F52:F151,"Motech",'👤 Tan'!I52:I151)+SUMIF('👤 Aoey'!F42:F141,"Motech",'👤 Aoey'!I42:I141)+SUMIF('👤 Other Sales'!F42:F141,"Motech",'👤 Other Sales'!I42:I141) -> 3411546 | D61: =IFERROR((SUMIF('👤 Mew'!F42:F228,"Motech",'👤 Mew'!I42:I228)+SUMIF('👤 Napat'!F42:F144,"Motech",'👤 Napat'!I42:I144)+SUMIF('👤 Tan'!F52:F151,"Motech",'👤 Tan'!I52:I151)+SUMIF('👤 Aoey'!F42:F141,"Motech",'👤 Aoey'!I42:I141)+SUMIF('👤 Other Sales'!F42:F141,"Motech",'👤 Other Sales'!I42:I141))/(SUM('👤 Mew'!I42:I228)+SUM('👤 Napat'!I42:I144)+SUM('👤 Tan'!I52:I151)+SUM('👤 Aoey'!I42:I141)+SUM('👤 Other Sales'!I42:I141)),0) -> 0.033180927
A62: Hybrida | B62: =COUNTIF('👤 Mew'!F42:F228,"Hybrida")+COUNTIF('👤 Napat'!F42:F144,"Hybrida")+COUNTIF('👤 Tan'!F52:F151,"Hybrida")+COUNTIF('👤 Aoey'!F42:F141,"Hybrida")+COUNTIF('👤 Other Sales'!F42:F141,"Hybrida") -> 1 | C62: =SUMIF('👤 Mew'!F42:F228,"Hybrida",'👤 Mew'!I42:I228)+SUMIF('👤 Napat'!F42:F144,"Hybrida",'👤 Napat'!I42:I144)+SUMIF('👤 Tan'!F52:F151,"Hybrida",'👤 Tan'!I52:I151)+SUMIF('👤 Aoey'!F42:F141,"Hybrida",'👤 Aoey'!I42:I141)+SUMIF('👤 Other Sales'!F42:F141,"Hybrida",'👤 Other Sales'!I42:I141) -> 210000 | D62: =IFERROR((SUMIF('👤 Mew'!F42:F228,"Hybrida",'👤 Mew'!I42:I228)+SUMIF('👤 Napat'!F42:F144,"Hybrida",'👤 Napat'!I42:I144)+SUMIF('👤 Tan'!F52:F151,"Hybrida",'👤 Tan'!I52:I151)+SUMIF('👤 Aoey'!F42:F141,"Hybrida",'👤 Aoey'!I42:I141)+SUMIF('👤 Other Sales'!F42:F141,"Hybrida",'👤 Other Sales'!I42:I141))/(SUM('👤 Mew'!I42:I228)+SUM('👤 Napat'!I42:I144)+SUM('👤 Tan'!I52:I151)+SUM('👤 Aoey'!I42:I141)+SUM('👤 Other Sales'!I42:I141)),0) -> 0.0020424742
A63: Other | B63: =COUNTIF('👤 Mew'!F42:F228,"Other")+COUNTIF('👤 Napat'!F42:F144,"Other")+COUNTIF('👤 Tan'!F52:F151,"Other")+COUNTIF('👤 Aoey'!F42:F141,"Other")+COUNTIF('👤 Other Sales'!F42:F141,"Other") -> 2 | C63: =SUMIF('👤 Mew'!F42:F228,"Other",'👤 Mew'!I42:I228)+SUMIF('👤 Napat'!F42:F144,"Other",'👤 Napat'!I42:I144)+SUMIF('👤 Tan'!F52:F151,"Other",'👤 Tan'!I52:I151)+SUMIF('👤 Aoey'!F42:F141,"Other",'👤 Aoey'!I42:I141)+SUMIF('👤 Other Sales'!F42:F141,"Other",'👤 Other Sales'!I42:I141) -> 20896 | D63: =IFERROR((SUMIF('👤 Mew'!F42:F228,"Other",'👤 Mew'!I42:I228)+SUMIF('👤 Napat'!F42:F144,"Other",'👤 Napat'!I42:I144)+SUMIF('👤 Tan'!F52:F151,"Other",'👤 Tan'!I52:I151)+SUMIF('👤 Aoey'!F42:F141,"Other",'👤 Aoey'!I42:I141)+SUMIF('👤 Other Sales'!F42:F141,"Other",'👤 Other Sales'!I42:I141))/(SUM('👤 Mew'!I42:I228)+SUM('👤 Napat'!I42:I144)+SUM('👤 Tan'!I52:I151)+SUM('👤 Aoey'!I42:I141)+SUM('👤 Other Sales'!I42:I141)),0) -> 0.00020323591

Sheet 👤 Mew
A1: 👤 MEW — Sales Pipeline & Performance
R3: Month | S3: Target | T3: Taken Orders (Deal Signed) | U3: Delivered Orders
A4: 📊 KPI DASHBOARD | R4: Jan | S4: 3000000 | T4: =SUMPRODUCT(IFERROR((MONTH(L42:L228)=1)*(YEAR(L42:L228)=2026),0)*I42:I228) -> 0 | U4: =SUMPRODUCT(IFERROR((MONTH(M42:M228)=1)*(YEAR(M42:M228)=2026),0)*I42:I228) -> 0
A5: Total Pipeline (THB) | E5: Weighted Pipeline (THB) | I5: Signed This Month (THB) | M5: Annual Target (THB) | R5: Feb | S5: 6000000 | T5: =SUMPRODUCT(IFERROR((MONTH(L58:L228)=2)*(YEAR(L58:L228)=2026),0)*I58:I228) -> 0 | U5: =SUMPRODUCT(IFERROR((MONTH(M58:M228)=2)*(YEAR(M58:M228)=2026),0)*I58:I228) -> 0
A6: =SUMIF(B42:B228,"<>Delivered",I42:I228) -> 8725490 | E6: =SUM(K42:K228) -> 33968159 | I6: =SUMPRODUCT((B42:B228="Deal Signed")*IFERROR((MONTH(L42:L228)=MONTH(TODAY()))*(YEAR(L42:L228)=YEAR(TODAY())),0)*I42:I228)+SUMPRODUCT((B42:B228="Delivered")*IFERROR((MONTH(L42:L228)=MONTH(TODAY()))*(YEAR(L42:L228)=YEAR(TODAY())),0)*I42:I228) -> 0 | M6: =SUM(S4:S15) -> 36000000 | R6: Mar | S6: 3000000 | T6: =SUMPRODUCT(IFERROR((MONTH(L58:L228)=3)*(YEAR(L58:L228)=2026),0)*I58:I228) -> 0 | U6: =SUMPRODUCT(IFERROR((MONTH(M58:M228)=3)*(YEAR(M58:M228)=2026),0)*I58:I228) -> 0
R7: Apr | S7: 3000000 | T7: =SUMPRODUCT(IFERROR((MONTH(L58:L228)=4)*(YEAR(L58:L228)=2026),0)*I58:I228) -> 0 | U7: =SUMPRODUCT(IFERROR((MONTH(M58:M228)=4)*(YEAR(M58:M228)=2026),0)*I58:I228) -> 0
R8: May | S8: 2500000 | T8: =SUMPRODUCT(IFERROR((MONTH(L58:L228)=5)*(YEAR(L58:L228)=2026),0)*I58:I228) -> 0 | U8: =SUMPRODUCT(IFERROR((MONTH(M58:M228)=5)*(YEAR(M58:M228)=2026),0)*I58:I228) -> 0
A9: 📋 PIPELINE BREAKDOWN | R9: Jun | S9: 1500000 | T9: =SUMPRODUCT(IFERROR((MONTH(L58:L228)=6)*(YEAR(L58:L228)=2026),0)*I58:I228) -> 0 | U9: =SUMPRODUCT(IFERROR((MONTH(M58:M228)=6)*(YEAR(M58:M228)=2026),0)*I58:I228) -> 0
A10: Stage | B10: # Deals | C10: Value (THB) | D10: % of Pipeline | F10: Priority | G10: # Deals | H10: Value (THB) | I10: % of Pipeline | R10: Jul | S10: 2500000 | T10: =SUMPRODUCT(IFERROR((MONTH(L58:L228)=7)*(YEAR(L58:L228)=2026),0)*I58:I228) -> 0 | U10: =SUMPRODUCT(IFERROR((MONTH(M58:M228)=7)*(YEAR(M58:M228)=2026),0)*I58:I228) -> 0
A11: Interest | B11: =COUNTIF(B42:B228,"Interest") -> 5 | C11: =SUMIF(B42:B228,"Interest",I42:I228) -> 5415555 | D11: =IFERROR(SUMIF(B42:B228,"Interest",I42:I228)/SUM(I42:I228),0) -> 0.15438959 | F11: High | G11: =COUNTIF(D42:D228,"High") -> 25 | H11: =SUMIF(D42:D228,"High",I42:I228) -> 25535606 | I11: =IFERROR(SUMIF(D42:D228,"High",I42:I228)/SUM(I42:I228),0) -> 0.72798294 | R11: Aug | S11: 2500000 | T11: =SUMPRODUCT(IFERROR((MONTH(L58:L228)=8)*(YEAR(L58:L228)=2026),0)*I58:I228) -> 0 | U11: =SUMPRODUCT(IFERROR((MONTH(M58:M228)=8)*(YEAR(M58:M228)=2026),0)*I58:I228) -> 0
A12: Send PI | B12: =COUNTIF(B42:B228,"Send PI") -> 0 | C12: =SUMIF(B42:B228,"Send PI",I42:I228) -> 0 | D12: =IFERROR(SUMIF(B42:B228,"Send PI",I42:I228)/SUM(I42:I228),0) -> 0 | F12: Medium | G12: =COUNTIF(D42:D228,"Medium") -> 37 | H12: =SUMIF(D42:D228,"Medium",I42:I228) -> 7513608 | I12: =IFERROR(SUMIF(D42:D228,"Medium",I42:I228)/SUM(I42:I228),0) -> 0.21420202 | R12: Sep | S12: 2500000 | T12: =SUMPRODUCT(IFERROR((MONTH(L58:L228)=9)*(YEAR(L58:L228)=2026),0)*I58:I228) -> 0 | U12: =SUMPRODUCT(IFERROR((MONTH(M58:M228)=9)*(YEAR(M58:M228)=2026),0)*I58:I228) -> 0
A13: Negotiating | B13: =COUNTIF(B42:B228,"Negotiating") -> 0 | C13: =SUMIF(B42:B228,"Negotiating",I42:I228) -> 0 | D13: =IFERROR(SUMIF(B42:B228,"Negotiating",I42:I228)/SUM(I42:I228),0) -> 0 | F13: Low | G13: =COUNTIF(D42:D228,"Low") -> 58 | H13: =SUMIF(D42:D228,"Low",I42:I228) -> 2027990 | I13: =IFERROR(SUMIF(D42:D228,"Low",I42:I228)/SUM(I42:I228),0) -> 0.057815041 | R13: Oct | S13: 3500000 | T13: =SUMPRODUCT(IFERROR((MONTH(L58:L228)=10)*(YEAR(L58:L228)=2026),0)*I58:I228) -> 0 | U13: =SUMPRODUCT(IFERROR((MONTH(M58:M228)=10)*(YEAR(M58:M228)=2026),0)*I58:I228) -> 0
A14: Deal Signed | B14: =COUNTIF(B42:B228,"Deal Signed") -> 16 | C14: =SUMIF(B42:B228,"Deal Signed",I42:I228) -> 3309935 | D14: =IFERROR(SUMIF(B42:B228,"Deal Signed",I42:I228)/SUM(I42:I228),0) -> 0.094361426 | F14: 🎯 Monthly Progress vs Target | R14: Nov | S14: 3000000 | T14: =SUMPRODUCT(IFERROR((MONTH(L58:L228)=11)*(YEAR(L58:L228)=2026),0)*I58:I228) -> 0 | U14: =SUMPRODUCT(IFERROR((MONTH(M58:M228)=11)*(YEAR(M58:M228)=2026),0)*I58:I228) -> 0
A15: Delivered | B15: =COUNTIF(B42:B228,"Delivered") -> 99 | C15: =SUMIF(B42:B228,"Delivered",I42:I228) -> 26351714 | D15: =IFERROR(SUMIF(B42:B228,"Delivered",I42:I228)/SUM(I42:I228),0) -> 0.75124899 | F15: ="Signed this month: "&TEXT(SUMPRODUCT((B42:B228="Deal Signed")*IFERROR((MONTH(L42:L228)=MONTH(TODAY()))*(YEAR(L42:L228)=YEAR(TODAY())),0)*I42:I228)+SUMPRODUCT((B42:B228="Delivered")*IFERROR((MONTH(L42:L228)=MONTH(TODAY()))*(YEAR(L42:L228)=YEAR(TODAY())),0)*I42:I228),"#,##0")&" THB | Target: "&TEXT('⚙ Control Panel'!$A$23,"#,##0")&" THB" -> Signed this month: 0 THB | Target: 3,000,000 THB | R15: Dec | S15: 3000000 | T15: =SUMPRODUCT(IFERROR((MONTH(L58:L228)=12)*(YEAR(L58:L228)=2026),0)*I58:I228) -> 0 | U15: =SUMPRODUCT(IFERROR((MONTH(M58:M228)=12)*(YEAR(M58:M228)=2026),0)*I58:I228) -> 0
A17: 📈 MONTHLY SALES TREND — 2026 (Target vs Taken vs Delivered)
A41: Project / Client | B41: Stage | C41: Segment | D41: Priority | E41: Product Category | F41: Brand | G41: Fee Structure | H41: Specialization | I41: Deal Value (THB) | J41: Win Prob (%) | K41: Weighted Value (THB) | L41: Order Taken Date | M41: Delivered Date | N41: Est. Close Date | O41: Next Action | P41: Notes | Q41: Project Code
A42: สำนักงานตำรวจแห่งชาติ | B42: Delivered | C42: Gov | D42: Low | E42: Wooden | F42: Motech | G42: No fee | H42: Government | I42: 32196 | J42: 1 | K42: =IF(I42="",0,I42*J42) -> 32196 | M42: 46053 | N42: 46053 | Q42: PJ-2608-00023
A43: กองพลาธิการสำนักงานส่งกำลังบำรุง | B43: Delivered | C43: Gov | D43: Low | E43: Wooden | F43: Taiyo | G43: No fee | H43: Government | I43: 10070 | J43: 1 | K43: =IF(I43="",0,I43*J43) -> 10070 | M43: 46052 | N43: 46053 | Q43: PJ-2608-00024
A44: บ.เอพีพี ดีเวลลอปเม้น | B44: Delivered | C44: Private | D44: Low | E44: Chair | F44: Taiyo | G44: No fee | H44: Office | I44: 271532 | J44: 1 | K44: =IF(I44="",0,I44*J44) -> 271532 | M44: 46052 | N44: 46053 | Q44: PJ-2608-00025
A45: บ.ซิสเต็ม โลจิสติกส์ | B45: Delivered | C45: Private | D45: Low | E45: Wooden | F45: Motech | G45: No fee | H45: Office | I45: 21600 | J45: 1 | K45: =IF(I45="",0,I45*J45) -> 21600 | M45: 46052 | N45: 46053 | Q45: PJ-2608-00026
A46: บ.เอส.เค.สมาร์ท ไอเดีย | B46: Delivered | C46: Private | D46: Low | E46: Steel | F46: Taiyo | G46: Client to resell | H46: Office | I46: 9760 | J46: 1 | K46: =IF(I46="",0,I46*J46) -> 9760 | M46: 46052 | N46: 46053 | Q46: PJ-2608-00027
A47: บ.ไมด้า พร็อพเพอร์ตี้ | B47: Delivered | C47: Private | D47: Low | E47: Chair | F47: Taiyo | G47: No fee | H47: Office | I47: 4205 | J47: 1 | K47: =IF(I47="",0,I47*J47) -> 4205 | M47: 46052 | N47: 46053 | Q47: PJ-2608-00028
A48: บ.โดูล่า กรุ๊ป จำกัด | B48: Delivered | C48: Private | D48: Low | E48: Chair | F48: Other | G48: Client to resell | H48: Office | I48: 3930 | J48: 1 | K48: =IF(I48="",0,I48*J48) -> 3930 | M48: 46052 | N48: 46053 | Q48: PJ-2608-00029
A49: บ.ซิเลสติกา (ประเทศไทย) จำกัด | B49: Delivered | C49: Private | D49: High | E49: Steel | F49: Taiyo | G49: No fee | H49: Office | I49: 759490 | J49: 1 | K49: =IF(I49="",0,I49*J49) -> 759490 | M49: 46052 | N49: 46053 | Q49: PJ-2608-00030
A50: บ.เอเชีย คลีน อินดัสตรี | B50: Delivered | C50: Private | D50: Low | E50: Wooden | F50: Taiyo | G50: No fee | H50: Office | I50: 49502 | J50: 1 | K50: =IF(I50="",0,I50*J50) -> 49502 | M50: 46052 | N50: 46053 | Q50: PJ-2608-00031
A51: บ.โปรเน็ตเวิร์ค ซิสเต็มส์ | B51: Delivered | C51: Private | D51: Medium | E51: Wooden | F51: Taiyo | G51: Client to resell | H51: Education | I51: 103287 | J51: 1 | K51: =IF(I51="",0,I51*J51) -> 103287 | M51: 46052 | N51: 46053 | Q51: PJ-2608-00032
A52: บ.ทรานส์เพอร์เทชั่น | B52: Delivered | C52: Private | D52: Medium | E52: Wooden | F52: Taiyo | G52: Client to resell | H52: Education | I52: 102587 | J52: 1 | K52: =IF(I52="",0,I52*J52) -> 102587 | M52: 46052 | N52: 46053 | Q52: PJ-2608-00033
A53: บ.ไอคอน สตีล โปรดัคท์ | B53: Delivered | C53: Private | D53: High | E53: Chair | F53: Taiyo | G53: Client to resell | H53: Government | I53: 799984 | J53: 1 | K53: =IF(I53="",0,I53*J53) -> 799984 | M53: 46052 | N53: 46053 | Q53: PJ-2608-00034
... A78: วัดพระธรรมกาย | B78: Delivered | C78: Private | D78: Low | E78: Chair | F78: Taiyo | G78: No fee | H78: Office | I78: 4300 | J78: 1 | K78: =IF(I78="",0,I78*J78) -> 4300 | M78: 46085 | N78: 46085 | Q78: PJ-2608-00059
A79: บ.โคคูโย อินเตอร์เนชั่นแนล | B79: Delivered | C79: Private | D79: Low | F79: Taiyo | G79: No fee | H79: Office | I79: 9486 | J79: 1 | K79: =IF(I79="",0,I79*J79) -> 9486 | M79: 46086 | N79: 46086 | Q79: PJ-2608-00060
A80: บ.เอพีพี ดีเวลลอปเม้น | B80: Delivered | C80: Private | D80: High | E80: Wooden | F80: Taiyo | G80: No fee | H80: Education | I80: 681907 | J80: 1 | K80: =IF(I80="",0,I80*J80) -> 681907 | M80: 46087 | N80: 46087 | Q80: PJ-2608-00061
A81: บ.ไมด้า พร็อพเพอร์ตี้ | B81: Delivered | C81: Private | D81: Low | E81: Chair | F81: Taiyo | G81: No fee | H81: Office | I81: 3645 | J81: 1 | K81: =IF(I81="",0,I81*J81) -> 3645 | M81: 46088 | N81: 46088 | Q81: PJ-2608-00062
A82: บ.บรรเจิด อินฟินิท จำกัด | B82: Delivered | C82: Private | D82: Low | E82: Chair | F82: Motech | G82: Client to resell | H82: Office | I82: 23034 | J82: 1 | K82: =IF(I82="",0,I82*J82) -> 23034 | M82: 46089 | N82: 46089 | Q82: PJ-2608-00063
A83: บ.โมดูลาร์ จำกัด | B83: Delivered | C83: Private | D83: Low | E83: Steel | F83: Taiyo | G83: Client to resell | H83: Office | I83: 18995 | J83: 1 | K83: =IF(I83="",0,I83*J83) -> 18995 | M83: 46090 | N83: 46090 | Q83: PJ-2608-00064
A84: บ.ไฮบริด บิ้วท์ แอนด์ คอนสตรัคชั่น | B84: Delivered | C84: Private | D84: Low | E84: Chair | F84: Taiyo | G84: Client to resell | H84: Office | I84: 40033 | J84: 1 | K84: =IF(I84="",0,I84*J84) -> 40033 | M84: 46091 | N84: 46091 | Q84: PJ-2608-00065
A85: รร.กวดวิชาจิราธิวรรธน์ | B85: Delivered | C85: Private | D85: Low | E85: Steel | F85: Taiyo | G85: No fee | H85: Education | I85: 3500 | J85: 1 | K85: =IF(I85="",0,I85*J85) -> 3500 | M85: 46092 | N85: 46092 | Q85: PJ-2608-00066
A86: บ.โปรเน็ตเวิร์ค ซิสเต็มส์ | B86: Delivered | C86: Private | D86: Medium | E86: Wooden | F86: Taiyo | G86: Client to resell | H86: Education | I86: 10002 | J86: 1 | K86: =IF(I86="",0,I86*J86) -> 10002 | M86: 46093 | N86: 46093 | Q86: PJ-2608-00067
A87: บ.ทรานส์เพอร์เทชั่น | B87: Delivered | C87: Private | D87: Medium | E87: Wooden | F87: Taiyo | G87: Client to resell | H87: Education | I87: 540086 | J87: 1 | K87: =IF(I87="",0,I87*J87) -> 540086 | M87: 46094 | N87: 46094 | Q87: PJ-2608-00068
A88: บ.ไอคอน สตีล โปรดัคท์ | B88: Delivered | C88: Private | D88: High | E88: Chair | F88: Taiyo | G88: Client to resell | H88: Government | I88: 820800 | J88: 1 | K88: =IF(I88="",0,I88*J88) -> 820800 | M88: 46095 | N88: 46095 | Q88: PJ-2608-00069
A89: บ.บ๊อกบราวน์ จำกัด | B89: Delivered | C89: Private | D89: Medium | E89: Wooden | F89: Taiyo | G89: Client to resell | H89: Education | I89: 141400 | J89: 1 | K89: =IF(I89="",0,I89*J89) -> 141400 | M89: 46096 | N89: 46096 | Q89: PJ-2608-00070
...

Sheet 👤 Napat
A1: 👤 NAPAT — Sales Pipeline & Performance
S3: Month | T3: Target | U3: Taken Orders (Deal Signed) | V3: Delivered Orders
A4: 📊 KPI DASHBOARD | S4: Jan | T4: 1500000 | U4: =SUMPRODUCT(IFERROR((MONTH(L42:L144)=1)*(YEAR(L42:L144)=2026),0)*I42:I144) -> 0 | V4: =SUMPRODUCT(IFERROR((MONTH(M42:M144)=1)*(YEAR(M42:M144)=2026),0)*I42:I144) -> 0
A5: Total Pipeline (THB) | E5: Weighted Pipeline (THB) | I5: Signed This Month (THB) | M5: Annual Target (THB) | S5: Feb | T5: 2000000 | U5: =SUMPRODUCT(IFERROR((MONTH(L42:L144)=2)*(YEAR(L42:L144)=2026),0)*I42:I144) -> 0 | V5: =SUMPRODUCT(IFERROR((MONTH(M42:M144)=2)*(YEAR(M42:M144)=2026),0)*I42:I144) -> 0
A6: =SUMIF(B42:B144,"<>Delivered",I42:I144) -> 15480135 | E6: =SUM(K42:K144) -> 11678202 | I6: =SUMPRODUCT((B42:B144="Deal Signed")*IFERROR((MONTH(L42:L144)=MONTH(TODAY()))*(YEAR(L42:L144)=YEAR(TODAY())),0)*I42:I144)+SUMPRODUCT((B42:B144="Delivered")*IFERROR((MONTH(L42:L144)=MONTH(TODAY()))*(YEAR(L42:L144)=YEAR(TODAY())),0)*I42:I144) -> 0 | M6: =SUM(T4:T15) -> 36000000 | S6: Mar | T6: 4000000 | U6: =SUMPRODUCT(IFERROR((MONTH(L42:L144)=3)*(YEAR(L42:L144)=2026),0)*I42:I144) -> 0 | V6: =SUMPRODUCT(IFERROR((MONTH(M42:M144)=3)*(YEAR(M42:M144)=2026),0)*I42:I144) -> 0
S7: Apr | T7: 4000000 | U7: =SUMPRODUCT(IFERROR((MONTH(L42:L144)=4)*(YEAR(L42:L144)=2026),0)*I42:I144) -> 0 | V7: =SUMPRODUCT(IFERROR((MONTH(M42:M144)=4)*(YEAR(M42:M144)=2026),0)*I42:I144) -> 0
S8: May | T8: 3000000 | U8: =SUMPRODUCT(IFERROR((MONTH(L42:L144)=5)*(YEAR(L42:L144)=2026),0)*I42:I144) -> 0 | V8: =SUMPRODUCT(IFERROR((MONTH(M42:M144)=5)*(YEAR(M42:M144)=2026),0)*I42:I144) -> 0
A9: 📋 PIPELINE BREAKDOWN | S9: Jun | T9: 3500000 | U9: =SUMPRODUCT(IFERROR((MONTH(L42:L144)=6)*(YEAR(L42:L144)=2026),0)*I42:I144) -> 0 | V9: =SUMPRODUCT(IFERROR((MONTH(M42:M144)=6)*(YEAR(M42:M144)=2026),0)*I42:I144) -> 0
A10: Stage | B10: # Deals | C10: Value (THB) | D10: % of Pipeline | F10: Priority | G10: # Deals | H10: Value (THB) | I10: % of Pipeline | S10: Jul | T10: 3000000 | U10: =SUMPRODUCT(IFERROR((MONTH(L42:L144)=7)*(YEAR(L42:L144)=2026),0)*I42:I144) -> 0 | V10: =SUMPRODUCT(IFERROR((MONTH(M42:M144)=7)*(YEAR(M42:M144)=2026),0)*I42:I144) -> 0
A11: Interest | B11: =COUNTIF(B42:B144,"Interest") -> 2 | C11: =SUMIF(B42:B144,"Interest",I42:I144) -> 15453958 | D11: =IFERROR(SUMIF(B42:B144,"Interest",I42:I144)/SUM(I42:I144),0) -> 0.9457419 | F11: High | G11: =COUNTIF(D42:D144,"High") -> 9 | H11: =SUMIF(D42:D144,"High",I42:I144) -> 16314389 | I11: =IFERROR(SUMIF(D42:D144,"High",I42:I144)/SUM(I42:I144),0) -> 0.99839804 | S11: Aug | T11: 3000000 | U11: =SUMPRODUCT(IFERROR((MONTH(L42:L144)=8)*(YEAR(L42:L144)=2026),0)*I42:I144) -> 0 | V11: =SUMPRODUCT(IFERROR((MONTH(M42:M144)=8)*(YEAR(M42:M144)=2026),0)*I42:I144) -> 0
A12: Send PI | B12: =COUNTIF(B42:B144,"Send PI") -> 0 | C12: =SUMIF(B42:B144,"Send PI",I42:I144) -> 0 | D12: =IFERROR(SUMIF(B42:B144,"Send PI",I42:I144)/SUM(I42:I144),0) -> 0 | F12: Medium | G12: =COUNTIF(D42:D144,"Medium") -> 0 | H12: =SUMIF(D42:D144,"Medium",I42:I144) -> 0 | I12: =IFERROR(SUMIF(D42:D144,"Medium",I42:I144)/SUM(I42:I144),0) -> 0 | S12: Sep | T12: 3000000 | U12: =SUMPRODUCT(IFERROR((MONTH(L42:L144)=9)*(YEAR(L42:L144)=2026),0)*I42:I144) -> 0 | V12: =SUMPRODUCT(IFERROR((MONTH(M42:M144)=9)*(YEAR(M42:M144)=2026),0)*I42:I144) -> 0
A13: Negotiating | B13: =COUNTIF(B42:B144,"Negotiating") -> 0 | C13: =SUMIF(B42:B144,"Negotiating",I42:I144) -> 0 | D13: =IFERROR(SUMIF(B42:B144,"Negotiating",I42:I144)/SUM(I42:I144),0) -> 0 | F13: Low | G13: =COUNTIF(D42:D144,"Low") -> 1 | H13: =SUMIF(D42:D144,"Low",I42:I144) -> 26177 | I13: =IFERROR(SUMIF(D42:D144,"Low",I42:I144)/SUM(I42:I144),0) -> 0.0016019641 | S13: Oct | T13: 3000000 | U13: =SUMPRODUCT(IFERROR((MONTH(L42:L144)=10)*(YEAR(L42:L144)=2026),0)*I42:I144) -> 0 | V13: =SUMPRODUCT(IFERROR((MONTH(M42:M144)=10)*(YEAR(M42:M144)=2026),0)*I42:I144) -> 0
A14: Deal Signed | B14: =COUNTIF(B42:B144,"Deal Signed") -> 0 | C14: =SUMIF(B42:B144,"Deal Signed",I42:I144) -> 0 | D14: =IFERROR(SUMIF(B42:B144,"Deal Signed",I42:I144)/SUM(I42:I144),0) -> 0 | F14: 🎯 Monthly Progress vs Target | S14: Nov | T14: 3000000 | U14: =SUMPRODUCT(IFERROR((MONTH(L42:L144)=11)*(YEAR(L42:L144)=2026),0)*I42:I144) -> 0 | V14: =SUMPRODUCT(IFERROR((MONTH(M42:M144)=11)*(YEAR(M42:M144)=2026),0)*I42:I144) -> 0
A15: Delivered | B15: =COUNTIF(B42:B144,"Delivered") -> 7 | C15: =SUMIF(B42:B144,"Delivered",I42:I144) -> 860431 | D15: =IFERROR(SUMIF(B42:B144,"Delivered",I42:I144)/SUM(I42:I144),0) -> 0.052656132 | F15: ="Signed this month: "&TEXT(SUMPRODUCT((B42:B144="Deal Signed")*IFERROR((MONTH(L42:L144)=MONTH(TODAY()))*(YEAR(L42:L144)=YEAR(TODAY())),0)*I42:I144)+SUMPRODUCT((B42:B144="Delivered")*IFERROR((MONTH(L42:L144)=MONTH(TODAY()))*(YEAR(L42:L144)=YEAR(TODAY())),0)*I42:I144),"#,##0")&" THB | Target: "&TEXT('⚙ Control Panel'!$A$23,"#,##0")&" THB" -> Signed this month: 0 THB | Target: 3,000,000 THB | S15: Dec | T15: 3000000 | U15: =SUMPRODUCT(IFERROR((MONTH(L42:L144)=12)*(YEAR(L42:L144)=2026),0)*I42:I144) -> 0 | V15: =SUMPRODUCT(IFERROR((MONTH(M42:M144)=12)*(YEAR(M42:M144)=2026),0)*I42:I144) -> 0
A17: 📈 MONTHLY SALES TREND — 2026 (Target vs Taken vs Delivered)
A41: Project / Client | B41: Stage | C41: Segment | D41: Priority | E41: Product Category | F41: Brand | G41: Fee Structure | H41: Specialization | I41: Deal Value (THB) | J41: Win Prob (%) | K41: Weighted Value (THB) | L41: Order Taken Date | M41: Delivered Date | N41: Est. Close Date | O41: Next Action | P41: Notes | Q41: Project Code
A42: กรมพลาธิการทหารอากาศ | B42: Delivered | C42: Gov | D42: High | E42: Steel | F42: Taiyo | G42: No fee | H42: Government | I42: 290000 | J42: 1 | K42: =I42*J42 -> 290000 | L42: 20/02/2026 | M42: 46113 | Q42: PJ-2608-00143
A43: บจก. อาร์ เอ็ม ที อะไหล่ (สำนักงานใหญ่) | B43: Delivered | C43: Private | D43: High | E43: Chair | F43: Sunon | G43: No fee | H43: Office | I43: 7137 | J43: 1 | K43: =IF(I43="",0,I43*J43) -> 7137 | L43: 46032 | M43: 46146 | Q43: PJ-2608-00144
A44: บจก. อาร์ เอ็ม ที อะไหล่ (สำนักงานใหญ่) | B44: Delivered | C44: Private | D44: High | E44: Wooden | F44: Sunon | G44: No fee | H44: Office | I44: 305576 | J44: 1 | K44: =IF(I44="",0,I44*J44) -> 305576 | L44: 46143 | M44: 46299 | Q44: PJ-2608-00145
A45: บริษัท จิกลิโอ จำกัด | B45: Delivered | C45: Private | D45: High | E45: Chair | F45: Sunon | G45: No fee | H45: Office | I45: 10093 | J45: 1 | K45: =IF(I45="",0,I45*J45) -> 10093 | L45: 46038 | M45: 46146 | Q45: PJ-2608-00146
A46: แม่คะนิ้ง ครีเอทีพ จำกัด | B46: Delivered | C46: Gov | D46: High | E46: Steel | F46: Sunon | G46: No fee | H46: Hospital & Wellness | I46: 40092 | J46: 1 | K46: =IF(I46="",0,I46*J46) -> 40092 | L46: 46069 | M46: 18/04/2026 | Q46: PJ-2608-00147
A47: บริษัท สตาร์ร์ค แมนูแฟคเซอร์ริ่ง จากัด | B47: Delivered | C47: Private | D47: High | E47: Wooden | F47: Motech | G47: Client to resell | H47: Office | I47: 121000 | J47: 1 | K47: =IF(I47="",0,I47*J47) -> 121000 | L47: 46055 | M47: 21/02/2026 | Q47: PJ-2608-00148
A48: บริษัท สตาร์ร์ค แมนูแฟคเซอร์ริ่ง จากัด | B48: Delivered | C48: Private | D48: High | E48: Wooden | F48: Motech | G48: Client to resell | H48: Office | I48: 86533 | J48: 1 | K48: =IF(I48="",0,I48*J48) -> 86533 | L48: 46056 | M48: 26/02/2026 | P48: ลูกค้าไม่มีfeedback ทำเสนอราคาทั้งหมด 3 ครั้ง | Q48: PJ-2608-00149
A49: บริษัท แอโรกรีต (ประเทศไทย) จำกัด | B49: Lost | C49: Private | D49: Low | E49: Chair | F49: Sunon | G49: No fee | H49: Office | I49: 26177 | J49: 0 | K49: =IF(I49="",0,I49*J49) -> 0 | P49: ลููกค้าไม่มีงบประมาณชะลอการซื้อ | Q49: PJ-2608-00150
A50: กฟภ เขต 2 จ.อุบลราชธานี | B50: Interest | C50: Gov | D50: High | E50: Wooden | F50: Sunon | G50: Referral % | H50: Government | I50: 10656762 | J50: 0.7 | K50: =IF(I50="",0,I50*J50) -> 7459733.4 | N50: 46382 | O50: ติดตามเรื่องกำหนดงานประมูล | Q50: PJ-2608-00151
A51: สถาบันบัณฑิตพัฒนศิลป์ (วังหน้า) | B51: Interest | C51: Gov | D51: High | E51: Chair | F51: Sunon | G51: Referral % | H51: Office | I51: 4797196 | J51: 0.7 | K51: =IF(I51="",0,I51*J51) -> 3358037.2 | N51: 46321 | O51: ติดตามเดือน พค26 | P51: คาดว่างานจะปิดภายในปี26 | Q51: PJ-2608-00152
K52: =IF(I52="",0,I52*J52) -> 0
K53: =IF(I53="",0,I53*J53) -> 0
K54: =IF(I54="",0,I54*J54) -> 0
K55: =IF(I55="",0,I55*J55) -> 0
K56: =IF(I56="",0,I56*J56) -> 0
K57: =IF(I57="",0,I57*J57) -> 0
K58: =IF(I58="",0,I58*J58) -> 0
K59: =IF(I59="",0,I59*J59) -> 0
K60: =IF(I60="",0,I60*J60) -> 0
K61: =IF(I61="",0,I61*J61) -> 0
K62: =IF(I62="",0,I62*J62) -> 0
K63: =IF(I63="",0,I63*J63) -> 0
... K144: =IF(I144="",0,I144*J144) -> 0

Sheet 👤 Tan
A1: 👤 TAN — Sales Pipeline & Performance
S3: Month | T3: Target | U3: Taken Orders (Deal Signed) | V3: Delivered Orders
A4: 📊 KPI DASHBOARD | S4: Jan | T4: 1500000 | U4: =SUMPRODUCT(IFERROR((MONTH(L52:L151)=1)*(YEAR(L52:L151)=2026),0)*I52:I151) -> 0 | V4: =SUMPRODUCT(IFERROR((MONTH(M52:M151)=1)*(YEAR(M52:M151)=2026),0)*I52:I151) -> 0
A5: Total Pipeline (THB) | E5: Weighted Pipeline (THB) | I5: Signed This Month (THB) | M5: Annual Target (THB) | S5: Feb | T5: 2000000 | U5: =SUMPRODUCT(IFERROR((MONTH(L52:L151)=2)*(YEAR(L52:L151)=2026),0)*I52:I151) -> 0 | V5: =SUMPRODUCT(IFERROR((MONTH(M52:M151)=2)*(YEAR(M52:M151)=2026),0)*I52:I151) -> 0
A6: =SUMIF(B52:B151,"<>Delivered",I52:I151) -> 50605750 | E6: =SUM(K52:K151) -> 48716158 | I6: =SUMPRODUCT((B52:B151="Deal Signed")*IFERROR((MONTH(L52:L151)=MONTH(TODAY()))*(YEAR(L52:L151)=YEAR(TODAY())),0)*I52:I151)+SUMPRODUCT((B52:B151="Delivered")*IFERROR((MONTH(L52:L151)=MONTH(TODAY()))*(YEAR(L52:L151)=YEAR(TODAY())),0)*I52:I151) -> 0 | M6: =SUM(T4:T15) -> 36000000 | S6: Mar | T6: 4000000 | U6: =SUMPRODUCT(IFERROR((MONTH(L52:L151)=3)*(YEAR(L52:L151)=2026),0)*I52:I151) -> 0 | V6: =SUMPRODUCT(IFERROR((MONTH(M52:M151)=3)*(YEAR(M52:M151)=2026),0)*I52:I151) -> 0
S7: Apr | T7: 4000000 | U7: =SUMPRODUCT(IFERROR((MONTH(L52:L151)=4)*(YEAR(L52:L151)=2026),0)*I52:I151) -> 0 | V7: =SUMPRODUCT(IFERROR((MONTH(M52:M151)=4)*(YEAR(M52:M151)=2026),0)*I52:I151) -> 0
S8: May | T8: 3000000 | U8: =SUMPRODUCT(IFERROR((MONTH(L52:L151)=5)*(YEAR(L52:L151)=2026),0)*I52:I151) -> 0 | V8: =SUMPRODUCT(IFERROR((MONTH(M52:M151)=5)*(YEAR(M52:M151)=2026),0)*I52:I151) -> 0
A9: 📋 PIPELINE BREAKDOWN | S9: Jun | T9: 3500000 | U9: =SUMPRODUCT(IFERROR((MONTH(L52:L151)=6)*(YEAR(L52:L151)=2026),0)*I52:I151) -> 0 | V9: =SUMPRODUCT(IFERROR((MONTH(M52:M151)=6)*(YEAR(M52:M151)=2026),0)*I52:I151) -> 0
A10: Stage | B10: # Deals | C10: Value (THB) | D10: % of Pipeline | F10: Priority | G10: # Deals | H10: Value (THB) | I10: % of Pipeline | S10: Jul | T10: 3000000 | U10: =SUMPRODUCT(IFERROR((MONTH(L52:L151)=7)*(YEAR(L52:L151)=2026),0)*I52:I151) -> 0 | V10: =SUMPRODUCT(IFERROR((MONTH(M52:M151)=7)*(YEAR(M52:M151)=2026),0)*I52:I151) -> 0
A11: Interest | B11: =COUNTIF(B52:B151,"Interest") -> 2 | C11: =SUMIF(B52:B151,"Interest",I52:I151) -> 4383424 | D11: =IFERROR(SUMIF(B52:B151,"Interest",I52:I151)/SUM(I52:I151),0) -> 0.08661909 | F11: High | G11: =COUNTIF(D52:D151,"High") -> 14 | H11: =SUMIF(D52:D151,"High",I52:I151) -> 48322326 | I11: =IFERROR(SUMIF(D52:D151,"High",I52:I151)/SUM(I52:I151),0) -> 0.95487817 | S11: Aug | T11: 3000000 | U11: =SUMPRODUCT(IFERROR((MONTH(L52:L151)=8)*(YEAR(L52:L151)=2026),0)*I52:I151) -> 0 | V11: =SUMPRODUCT(IFERROR((MONTH(M52:M151)=8)*(YEAR(M52:M151)=2026),0)*I52:I151) -> 0
A12: Send PI | B12: =COUNTIF(B52:B151,"Send PI") -> 3 | C12: =SUMIF(B52:B151,"Send PI",I52:I151) -> 2332018 | D12: =IFERROR(SUMIF(B52:B151,"Send PI",I52:I151)/SUM(I52:I151),0) -> 0.046082076 | F12: Medium | G12: =COUNTIF(D52:D151,"Medium") -> 1 | H12: =SUMIF(D52:D151,"Medium",I52:I151) -> 2283424 | I12: =IFERROR(SUMIF(D52:D151,"Medium",I52:I151)/SUM(I52:I151),0) -> 0.045121829 | S12: Sep | T12: 3000000 | U12: =SUMPRODUCT(IFERROR((MONTH(L52:L151)=9)*(YEAR(L52:L151)=2026),0)*I52:I151) -> 0 | V12: =SUMPRODUCT(IFERROR((MONTH(M52:M151)=9)*(YEAR(M52:M151)=2026),0)*I52:I151) -> 0
A13: Negotiating | B13: =COUNTIF(B52:B151,"Negotiating") -> 3 | C13: =SUMIF(B52:B151,"Negotiating",I52:I151) -> 3082224 | D13: =IFERROR(SUMIF(B52:B151,"Negotiating",I52:I151)/SUM(I52:I151),0) -> 0.060906597 | F13: Low | G13: =COUNTIF(D52:D151,"Low") -> 0 | H13: =SUMIF(D52:D151,"Low",I52:I151) -> 0 | I13: =IFERROR(SUMIF(D52:D151,"Low",I52:I151)/SUM(I52:I151),0) -> 0 | S13: Oct | T13: 3000000 | U13: =SUMPRODUCT(IFERROR((MONTH(L52:L151)=10)*(YEAR(L52:L151)=2026),0)*I52:I151) -> 0 | V13: =SUMPRODUCT(IFERROR((MONTH(M52:M151)=10)*(YEAR(M52:M151)=2026),0)*I52:I151) -> 0
A14: Deal Signed | B14: =COUNTIF(B52:B151,"Deal Signed") -> 7 | C14: =SUMIF(B52:B151,"Deal Signed",I52:I151) -> 40808084 | D14: =IFERROR(SUMIF(B52:B151,"Deal Signed",I52:I151)/SUM(I52:I151),0) -> 0.80639224 | F14: 🎯 Monthly Progress vs Target | S14: Nov | T14: 3000000 | U14: =SUMPRODUCT(IFERROR((MONTH(L52:L151)=11)*(YEAR(L52:L151)=2026),0)*I52:I151) -> 0 | V14: =SUMPRODUCT(IFERROR((MONTH(M52:M151)=11)*(YEAR(M52:M151)=2026),0)*I52:I151) -> 0
A15: Delivered | B15: =COUNTIF(B52:B151,"Delivered") -> 0 | C15: =SUMIF(B52:B151,"Delivered",I52:I151) -> 0 | D15: =IFERROR(SUMIF(B52:B151,"Delivered",I52:I151)/SUM(I52:I151),0) -> 0 | F15: ="Signed this month: "&TEXT(SUMPRODUCT((B52:B151="Deal Signed")*IFERROR((MONTH(L52:L151)=MONTH(TODAY()))*(YEAR(L52:L151)=YEAR(TODAY())),0)*I52:I151)+SUMPRODUCT((B52:B151="Delivered")*IFERROR((MONTH(L52:L151)=MONTH(TODAY()))*(YEAR(L52:L151)=YEAR(TODAY())),0)*I52:I151),"#,##0")&" THB | Target: "&TEXT('⚙ Control Panel'!$A$23,"#,##0")&" THB" -> Signed this month: 0 THB | Target: 3,000,000 THB | S15: Dec | T15: 3000000 | U15: =SUMPRODUCT(IFERROR((MONTH(L52:L151)=12)*(YEAR(L52:L151)=2026),0)*I52:I151) -> 0 | V15: =SUMPRODUCT(IFERROR((MONTH(M52:M151)=12)*(YEAR(M52:M151)=2026),0)*I52:I151) -> 0
A17: 📈 MONTHLY SALES TREND — 2026 (Target vs Taken vs Delivered)
A41: Project / Client | B41: Stage | C41: Segment | D41: Priority | E41: Product Category | F41: Brand | G41: Fee Structure | H41: Specialization | I41: Deal Value (THB) | J41: Win Prob (%) | K41: Weighted Value (THB) | L41: Order Taken Date | M41: Delivered Date | N41: Est. Close Date | O41: Next Action | P41: Notes | Q41: Project Code
A42: บ.คาปาดีไซน์บิลด์ | B42: Delivered | C42: Private | E42: Steel | F42: Taiyo | G42: No fee | H42: Government | I42: 248375 | J42: 1 | Q42: PJ-2608-00153
A43: หจก.ทอฟ้าโฮม | B43: Delivered | C43: Private | E43: Steel | F43: Taiyo | G43: No fee | H43: Government | I43: 354000 | J43: 1 | Q43: PJ-2608-00154
A44: อัยการศรีสะเกษ | B44: Delivered | C44: Gov | E44: Wooden | F44: Taiyo | G44: No fee | H44: Government | I44: 136284 | J44: 1 | Q44: PJ-2608-00155
